Workbook

Sheet 기성매출(정상기성)
A1: No. | B1: 구분 | C1: 중구분 | D1: 소구분 | E1: 당사투입일 | F1: 계약종결일 | G1: 협력사구분 | H1: 계약종결사유 | J1: 42411 | K1: 42441 | L1: 42471 | M1: 42501 | N1: 42531 | O1: 42561 | P1: 42591 | Q1: 42621 | R1: 42651 | S1: 42681 | T1: 42711 | U1: 42741 | V1: 42771 | W1: 42801 | X1: 42831 | Y1: 42861 | Z1: 42891 | AA1: 42921 | AB1: 42951 | AC1: 42981 | AD1: 43011 | AE1: 43041 | AF1: 43071 | AG1: 2018-01 | AH1: 43132 | AI1: 43161 | AJ1: 43191 | AK1: 43221 | AL1: 43281 | AM1: 43311 | AN1: 43341 | AO1: 43371 | AP1: 43401 | AQ1: 43431 | AR1: 43461 | AS1: 43491 | AT1: 43521 | AU1: 43551 | AV1: 43581 | AW1: 43611 | AX1: 43641 | AY1: 43671 | AZ1: 43701 | BA1: 43731 | BB1: 43761 | BC1: 43791 | BD1: 43821 | BE1: 43851 | BF1: 43881 | BG1: 43911 | BH1: 43941 | BI1: 43971 | BJ1: 44001 | BK1: 44031 | BL1: 44061 | BM1: 44091 | BN1: 44121 | BO1: 44151 | BP1: 44181 | BQ1: 44211 | BR1: 44241 | BS1: 44271 | BT1: 44301 | BU1: 44331 | BV1: 44361 | BW1: 44391 | BX1: 44421 | BY1: 44451 | BZ1: 44481 | CA1: 44511 | CB1: 44541 | CC1: 44571 | CD1: 44601 | CE1: 44631 | CF1: 44661 | CG1: 44691 | CH1: 44721 | CI1: 44751 | CJ1: 44781 | CK1: 44811 | CL1: 44841 | CM1: 44871 | CN1: 44901 | CO1: 44931 | CP1: 44961 | CQ1: 44991 | CR1: 45021 | CS1: 45051 | CT1: 45081 | CU1: 45111 | CV1: 45141 | CW1: 45171 | CX1: 45201 | CY1: 45231 | CZ1: 45261 | DA1: 45321 | DB1: 45351 | DC1: 45381 | DD1: 45411 | DE1: 45441 | DF1: 45471 | DG1: 45501 | DH1: 45531 | DI1: 45561 | DJ1: 45591 | DK1: (백만원)
A2: 1 | B2: 사업1 | C2: 협력1 | D2: 라인2 | E2: 42380 | F2: 43131 | G2: 정규 | H2: 경영악화 | J2: 453.327 | K2: 558.7399 | L2: 532.7579 | M2: 530.2251 | N2: 441.0694 | O2: 374.7732 | P2: 261.5682 | Q2: 343.0453 | R2: 615.4283 | S2: 865.4336 | T2: 628.6738 | U2: 524.0332 | V2: 498.3735 | W2: 588.6475 | X2: 523.3157 | Y2: 583.681 | Z2: 786.0001 | AA2: 728.4261 | AB2: 562.1748 | AC2: 585.5558 | AD2: 449.1202 | AE2: 553.6566 | AF2: 409.6134 | AG2: 141.1357 | AH2: 0 | AI2: 0 | AJ2: 0 | AK2: 0 | AL2: 0 | AM2: 0 | AN2: 0 | AO2: 0 | AP2: 0 | AQ2: 0 | AR2: 0 | AS2: 0 | AT2: 0 | AU2: 0 | AV2: 0 | AW2: 0 | AX2: 0 | AY2: 0 | AZ2: 0 | BA2: 0 | BB2: 0 | BC2: 0 | BD2: 0 | BE2: 0 | BF2: 0 | BG2: 0 | BH2: 0 | BI2: 0 | BJ2: 0 | BK2: 0 | BL2: 0 | BM2: 0 | BN2: 0 | BO2: 0 | BP2: 0 | BQ2: 0 | BR2: 0 | BS2: 0 | BT2: 0 | BU2: 0 | BV2: 0 | BW2: 0 | BX2: 0 | BY2: 0 | BZ2: 0 | CA2: 0 | CB2: 0 | CC2: 0 | CD2: 0 | CE2: 0 | CF2: 0 | CG2: 0 | CH2: 0 | CI2: 0 | CJ2: 0 | CK2: 0 | CL2: 0 | CM2: 0 | CN2: 0 | CO2: 0 | CP2: 0 | CQ2: 0 | CR2: 0 | CS2: 0 | CT2: 0 | CU2: 0 | CV2: 0 | CW2: 0 | CX2: 0 | CY2: 0 | CZ2: 0 | DA2: 0 | DB2: 0 | DC2: 0 | DD2: 0 | DE2: 0 | DF2: 0 | DG2: 0 | DH2: 0 | DI2: 0 | DJ2: 0
A3: 2 | B3: 사업1 | C3: 협력1 | D3: 외장1 | E3: 35149 | F3: 43131 | G3: 정규 | H3: 경영악화 | J3: 983.516 | K3: 1137.4032 | L3: 1026.0271 | M3: 925.1828 | N3: 1024.7134 | O3: 950.302 | P3: 757.2923 | Q3: 831.425 | R3: 850.7039 | S3: 977.9452 | T3: 1088.5089 | U3: 1053.4939 | V3: 869.0644 | W3: 1319.8517 | X3: 904.6311 | Y3: 504.2026 | Z3: 717.333 | AA3: 773.3102 | AB3: 389.0658 | AC3: 376.0973 | AD3: 200.158 | AE3: 131.0015 | AF3: 222.158 | AG3: 372.1489 | AH3: 0 | AI3: 0 | AJ3: 0 | AK3: 0 | AL3: 0 | AM3: 0 | AN3: 0 | AO3: 0 | AP3: 0 | AQ3: 0 | AR3: 0 | AS3: 0 | AT3: 0 | AU3: 0 | AV3: 0 | AW3: 0 | AX3: 0 | AY3: 0 | AZ3: 0 | BA3: 0 | BB3: 0 | BC3: 0 | BD3: 0 | BE3: 0 | BF3: 0 | BG3: 0 | BH3: 0 | BI3: 0 | BJ3: 0 | BK3: 0 | BL3: 0 | BM3: 0 | BN3: 0 | BO3: 0 | BP3: 0 | BQ3: 0 | BR3: 0 | BS3: 0 | BT3: 0 | BU3: 0 | BV3: 0 | BW3: 0 | BX3: 0 | BY3: 0 | BZ3: 0 | CA3: 0 | CB3: 0 | CC3: 0 | CD3: 0 | CE3: 0 | CF3: 0 | CG3: 0 | CH3: 0 | CI3: 0 | CJ3: 0 | CK3: 0 | CL3: 0 | CM3: 0 | CN3: 0 | CO3: 0 | CP3: 0 | CQ3: 0 | CR3: 0 | CS3: 0 | CT3: 0 | CU3: 0 | CV3: 0 | CW3: 0 | CX3: 0 | CY3: 0 | CZ3: 0 | DA3: 0 | DB3: 0 | DC3: 0 | DD3: 0 | DE3: 0 | DF3: 0 | DG3: 0 | DH3: 0 | DI3: 0 | DJ3: 0
A4: 3 | B4: 사업1 | C4: 협력1 | D4: 공사 | E4: 38071 | F4: 43159 | G4: 정규 | H4: 경영악화 | J4: 256.488 | K4: 345.1983 | L4: 346.409 | M4: 364.9295 | N4: 436.2587 | O4: 382.5379 | P4: 374.9276 | Q4: 383.5977 | R4: 272.6069 | S4: 400.5872 | T4: 470.6888 | U4: 336.6214 | V4: 279.3631 | W4: 354.7 | X4: 345.6489 | Y4: 514.2632 | Z4: 465.3339 | AA4: 531.5195 | AB4: 683.8954 | AC4: 645.9234 | AD4: 383.4593 | AE4: 518.6675 | AF4: 349.3319 | AG4: 315.8265 | AH4: 286.9703 | AI4: 0.0935 | AJ4: 0 | AK4: 0 | AL4: 0 | AM4: 0 | AN4: 0 | AO4: 0 | AP4: 0 | AQ4: 0 | AR4: 0 | AS4: 0 | AT4: 0 | AU4: 0 | AV4: 0 | AW4: 0 | AX4: 0 | AY4: 0 | AZ4: 0 | BA4: 0 | BB4: 0 | BC4: 0 | BD4: 0 | BE4: 0 | BF4: 0 | BG4: 0 | BH4: 0 | BI4: 0 | BJ4: 0 | BK4: 0 | BL4: 0 | BM4: 0 | BN4: 0 | BO4: 0 | BP4: 0 | BQ4: 0 | BR4: 0 | BS4: 0 | BT4: 0 | BU4: 0 | BV4: 0 | BW4: 0 | BX4: 0 | BY4: 0 | BZ4: 0 | CA4: 0 | CB4: 0 | CC4: 0 | CD4: 0 | CE4: 0 | CF4: 0 | CG4: 0 | CH4: 0 | CI4: 0 | CJ4: 0 | CK4: 0 | CL4: 0 | CM4: 0 | CN4: 0 | CO4: 0 | CP4: 0 | CQ4: 0 | CR4: 0 | CS4: 0 | CT4: 0 | CU4: 0 | CV4: 0 | CW4: 0 | CX4: 0 | CY4: 0 | CZ4: 0 | DA4: 0 | DB4: 0 | DC4: 0 | DD4: 0 | DE4: 0 | DF4: 0 | DG4: 0 | DH4: 0 | DI4: 0 | DJ4: 0
A5: 4 | B5: 사업2 | C5: 협력1 | D5: 라인2 | E5: 42292 | F5: 43190 | G5: 정규 | H5: 경영악화 | J5: 583.962 | K5: 467.977 | L5: 954.9428 | M5: 1046.2715 | N5: 369.3873 | O5: 403.2117 | P5: 361.1193 | Q5: 290.4382 | R5: 367.9593 | S5: 364.7032 | T5: 425.9354 | U5: 317.1039 | V5: 235.3092 | W5: 275.3885 | X5: 362.1109 | Y5: 287.2105 | Z5: 505.6637 | AA5: 672.8365 | AB5: 858.6145 | AC5: 1029.8255 | AD5: 1121.9262 | AE5: 1095.8291 | AF5: 584.4914 | AG5: 386.0519 | AH5: 96.8305 | AI5: 12.854 | AJ5: 0 | AK5: 0 | AL5: 156.6732 | AM5: 0 | AN5: 0 | AO5: 0 | AP5: 0 | AQ5: 0 | AR5: 0 | AS5: 0 | AT5: 0 | AU5: 0 | AV5: 0 | AW5: 0 | AX5: 0 | AY5: 0 | AZ5: 0 | BA5: 0 | BB5: 0 | BC5: 0 | BD5: 0 | BE5: 0 | BF5: 0 | BG5: 0 | BH5: 0 | BI5: 0 | BJ5: 0 | BK5: 0 | BL5: 0 | BM5: 0 | BN5: 0 | BO5: 0 | BP5: 0 | BQ5: 0 | BR5: 0 | BS5: 0 | BT5: 0 | BU5: 0 | BV5: 0 | BW5: 0 | BX5: 0 | BY5: 0 | BZ5: 0 | CA5: 0 | CB5: 0 | CC5: 0 | CD5: 0 | CE5: 0 | CF5: 0 | CG5: 0 | CH5: 0 | CI5: 0 | CJ5: 0 | CK5: 0 | CL5: 0 | CM5: 0 | CN5: 0 | CO5: 0 | CP5: 0 | CQ5: 0 | CR5: 0 | CS5: 0 | CT5: 0 | CU5: 0 | CV5: 0 | CW5: 0 | CX5: 0 | CY5: 0 | CZ5: 0 | DA5: 0 | DB5: 0 | DC5: 0 | DD5: 0 | DE5: 0 | DF5: 0 | DG5: 0 | DH5: 0 | DI5: 0 | DJ5: 0
A6: 5 | B6: 사업1 | C6: 협력1 | D6: 공사 | E6: 43161 | F6: 43312 | G6: 정규 | H6: 경영악화 | J6: 0 | K6: 0 | L6: 0 | M6: 0 | N6: 0 | O6: 0 | P6: 0 | Q6: 0 | R6: 0 | S6: 0 | T6: 0 | U6: 0 | V6: 0 | W6: 0 | X6: 0 | Y6: 0 | Z6: 0 | AA6: 0 | AB6: 0 | AC6: 0 | AD6: 0 | AE6: 0 | AF6: 0 | AG6: 0 | AH6: 0 | AI6: 557.5695 | AJ6: 577.2238 | AK6: 579.5762 | AL6: 460.3811 | AM6: 481.6792 | AN6: 0 | AO6: 0 | AP6: 0 | AQ6: 0 | AR6: 0 | AS6: 0 | AT6: 0 | AU6: 0 | AV6: 0 | AW6: 0 | AX6: 0 | AY6: 0 | AZ6: 0 | BA6: 0 | BB6: 0 | BC6: 0 | BD6: 0 | BE6: 0 | BF6: 0 | BG6: 0 | BH6: 0 | BI6: 0 | BJ6: 0 | BK6: 0 | BL6: 0 | BM6: 0 | BN6: 0 | BO6: 0 | BP6: 0 | BQ6: 0 | BR6: 0 | BS6: 0 | BT6: 0 | BU6: 0 | BV6: 0 | BW6: 0 | BX6: 0 | BY6: 0 | BZ6: 0 | CA6: 0 | CB6: 0 | CC6: 0 | CD6: 0 | CE6: 0 | CF6: 0 | CG6: 0 | CH6: 0 | CI6: 0 | CJ6: 0 | CK6: 0 | CL6: 0 | CM6: 0 | CN6: 0 | CO6: 0 | CP6: 0 | CQ6: 0 | CR6: 0 | CS6: 0 | CT6: 0 | CU6: 0 | CV6: 0 | CW6: 0 | CX6: 0 | CY6: 0 | CZ6: 0 | DA6: 0 | DB6: 0 | DC6: 0 | DD6: 0 | DE6: 0 | DF6: 0 | DG6: 0 | DH6: 0 | DI6: 0 | DJ6: 0
A7: 6 | B7: 사업2 | C7: 협력1 | D7: 라인2 | E7: 37956 | F7: 43312 | G7: 정규 | H7: 경영악화 | J7: 930.94 | K7: 1049.8822 | L7: 1064.2057 | M7: 997.5476 | N7: 947.7063 | O7: 834.0997 | P7: 482.7638 | Q7: 397.2185 | R7: 579.4922 | S7: 750.3251 | T7: 831.2399 | U7: 863.0028 | V7: 687.9662 | W7: 809.5136 | X7: 518.575 | Y7: 351.6913 | Z7: 363.695 | AA7: 490.1567 | AB7: 415.9464 | AC7: 346.179 | AD7: 199.8334 | AE7: 223.6371 | AF7: 258.8873 | AG7: 249.1035 | AH7: 182.8972 | AI7: 236.4058 | AJ7: 283.4772 | AK7: 333.8054 | AL7: 306.1659 | AM7: 378.7198 | AN7: 8.9779 | AO7: 0 | AP7: 0 | AQ7: 0 | AR7: 0 | AS7: 0 | AT7: 0 | AU7: 0 | AV7: 0 | AW7: 0 | AX7: 0 | AY7: 0 | AZ7: 0 | BA7: 0 | BB7: 0 | BC7: 0 | BD7: 0 | BE7: 0 | BF7: 0 | BG7: 0 | BH7: 0 | BI7: 0 | BJ7: 0 | BK7: 0 | BL7: 0 | BM7: 0 | BN7: 0 | BO7: 0 | BP7: 0 | BQ7: 0 | BR7: 0 | BS7: 0 | BT7: 0 | BU7: 0 | BV7: 0 | BW7: 0 | BX7: 0 | BY7: 0 | BZ7: 0 | CA7: 0 | CB7: 0 | CC7: 0 | CD7: 0 | CE7: 0 | CF7: 0 | CG7: 0 | CH7: 0 | CI7: 0 | CJ7: 0 | CK7: 0 | CL7: 0 | CM7: 0 | CN7: 0 | CO7: 0 | CP7: 0 | CQ7: 0 | CR7: 0 | CS7: 0 | CT7: 0 | CU7: 0 | CV7: 0 | CW7: 0 | CX7: 0 | CY7: 0 | CZ7: 0 | DA7: 0 | DB7: 0 | DC7: 0 | DD7: 0 | DE7: 0 | DF7: 0 | DG7: 0 | DH7: 0 | DI7: 0 | DJ7: 0
A8: 7 | B8: 사업1 | C8: 협력1 | D8: 외장1 | E8: 39783 | F8: 43570 | G8: 정규 | H8: 경영악화 | J8: 1435.36 | K8: 1679.354 | L8: 1686.5181 | M8: 1467.1483 | N8: 1360.8938 | O8: 937.7618 | P8: 833.4265 | Q8: 838.6153 | R8: 1030.6896 | S8: 1291.7399 | T8: 1396.6137 | U8: 1131.5454 | V8: 1032.2003 | W8: 1207.5422 | X8: 1061.0658 | Y8: 942.1495 | Z8: 1339.7652 | AA8: 1302.5985 | AB8: 698.7134 | AC8: 707.7552 | AD8: 571.6216 | AE8: 708.9029 | AF8: 604.2682 | AG8: 572.4377 | AH8: 400.4573 | AI8: 351.8887 | AJ8: 389.3899 | AK8: 524.2733 | AL8: 481.6205 | AM8: 485.6526 | AN8: 317.8697 | AO8: 301.4988 | AP8: 0 | AQ8: 0 | AR8: 0 | AS8: 0 | AT8: 0.4102 | AU8: 0 | AV8: 0 | AW8: 0.0368 | AX8: 0 | AY8: 0 | AZ8: 0 | BA8: 0 | BB8: 0 | BC8: 0 | BD8: 0 | BE8: 0 | BF8: 0 | BG8: 0 | BH8: 0 | BI8: 0 | BJ8: 0 | BK8: 0 | BL8: 0 | BM8: 0 | BN8: 0 | BO8: 0 | BP8: 0 | BQ8: 0 | BR8: 0 | BS8: 0 | BT8: 0 | BU8: 0 | BV8: 0 | BW8: 0 | BX8: 0 | BY8: 0 | BZ8: 0 | CA8: 0 | CB8: 0 | CC8: 0 | CD8: 0 | CE8: 0 | CF8: 0 | CG8: 0 | CH8: 0 | CI8: 0 | CJ8: 0 | CK8: 0 | CL8: 0 | CM8: 0 | CN8: 0 | CO8: 0 | CP8: 0 | CQ8: 0 | CR8: 0 | CS8: 0 | CT8: 0 | CU8: 0 | CV8: 0 | CW8: 0 | CX8: 0 | CY8: 0 | CZ8: 0 | DA8: 0 | DB8: 0 | DC8: 0 | DD8: 0 | DE8: 0 | DF8: 0 | DG8: 0 | DH8: 0 | DI8: 0 | DJ8: 0
A9: 8 | B9: 사업1 | C9: 협력1 | D9: 공사 | E9: 43161 | F9: 43793 | G9: 정규 | H9: 경영악화 | J9: 0 | K9: 0 | L9: 0 | M9: 0 | N9: 0 | O9: 0 | P9: 0 | Q9: 0 | R9: 0 | S9: 0 | T9: 0 | U9: 0 | V9: 0 | W9: 0 | X9: 0 | Y9: 0 | Z9: 0 | AA9: 0 | AB9: 0 | AC9: 0 | AD9: 0 | AE9: 0 | AF9: 0 | AG9: 0 | AH9: 0 | AI9: 565.0912 | AJ9: 604.2831 | AK9: 585.9307 | AL9: 447.9297 | AM9: 570.737 | AN9: 434.4747 | AO9: 483.81 | AP9: 427.6568 | AQ9: 565.1353 | AR9: 368.7702 | AS9: 290.5597 | AT9: 164.8238 | AU9: 3.8673 | AV9: 0 | AW9: 6.6675 | AX9: 26.6888 | AY9: 257.504 | AZ9: 355.5253 | BA9: 413.9322 | BB9: 605.3984 | BC9: 299.4632 | BD9: 0 | BE9: 0 | BF9: 0 | BG9: 0 | BH9: 0 | BI9: 0 | BJ9: 0 | BK9: 0 | BL9: 0 | BM9: 0 | BN9: 0 | BO9: 0 | BP9: 0 | BQ9: 0 | BR9: 0 | BS9: 0 | BT9: 0 | BU9: 0 | BV9: 0 | BW9: 0 | BX9: 0 | BY9: 0 | BZ9: 0 | CA9: 0 | CB9: 0 | CC9: 0 | CD9: 0 | CE9: 0 | CF9: 0 | CG9: 0 | CH9: 0 | CI9: 0 | CJ9: 0 | CK9: 0 | CL9: 0 | CM9: 0 | CN9: 0 | CO9: 0 | CP9: 0 | CQ9: 0 | CR9: 0 | CS9: 0 | CT9: 0 | CU9: 0 | CV9: 0 | CW9: 0 | CX9: 0 | CY9: 0 | CZ9: 0 | DA9: 0 | DB9: 0 | DC9: 0 | DD9: 0 | DE9: 0 | DF9: 0 | DG9: 0 | DH9: 0 | DI9: 0 | DJ9: 0
A10: 9 | B10: 사업1 | C10: 협력2 | D10: 지원 | E10: 39203 | F10: 43799 | G10: 정규 | H10: 경영악화 | J10: 600.174 | K10: 698.7824 | L10: 712.5239 | M10: 682.2686 | N10: 708.8328 | O10: 569.2783 | P10: 358.8489 | Q10: 507.878 | R10: 509.8913 | S10: 570.4224 | T10: 601.2218 | U10: 555.7593 | V10: 525.2391 | W10: 600.0745 | X10: 474.5013 | Y10: 391.344 | Z10: 446.8432 | AA10: 542.5439 | AB10: 449.2978 | AC10: 485.9595 | AD10: 377.3565 | AE10: 416.214 | AF10: 409.1535 | AG10: 182.883 | AH10: 220.662 | AI10: 176.8946 | AJ10: 199.5606 | AK10: 246.7398 | AL10: 264.5467 | AM10: 208.6711 | AN10: 154.6834 | AO10: 157.2506 | AP10: 164.6555 | AQ10: 229.4719 | AR10: 159.7929 | AS10: 177.07 | AT10: 160.7846 | AU10: 220.9532 | AV10: 377.8339 | AW10: 293.4919 | AX10: 245.4606 | AY10: 313.6124 | AZ10: 274.1406 | BA10: 309.9457 | BB10: 344.0788 | BC10: 335.1368 | BD10: 0 | BE10: 0 | BF10: 0 | BG10: 0 | BH10: 0 | BI10: 0 | BJ10: 0 | BK10: 0 | BL10: 0 | BM10: 0 | BN10: 0 | BO10: 0 | BP10: 0 | BQ10: 0 | BR10: 0 | BS10: 0 | BT10: 0 | BU10: 0 | BV10: 0 | BW10: 0 | BX10: 0 | BY10: 0 | BZ10: 0 | CA10: 0 | CB10: 0 | CC10: 0 | CD10: 0 | CE10: 0 | CF10: 0 | CG10: 0 | CH10: 0 | CI10: 0 | CJ10: 0 | CK10: 0 | CL10: 0 | CM10: 0 | CN10: 0 | CO10: 0 | CP10: 0 | CQ10: 0 | CR10: 0 | CS10: 0 | CT10: 0 | CU10: 0 | CV10: 0 | CW10: 0 | CX10: 0 | CY10: 0 | CZ10: 0 | DA10: 0 | DB10: 0 | DC10: 0 | DD10: 0 | DE10: 0 | DF10: 0 | DG10: 0 | DH10: 0 | DI10: 0 | DJ10: 0
A11: 10 | B11: 사업2 | C11: 협력1 | D11: 외장1 | E11: 41836 | F11: 43814 | G11: 정규 | H11: 경영악화 | J11: 1129.778 | K11: 1157.6521 | L11: 1066.3825 | M11: 938.3066 | N11: 954.3481 | O11: 839.3905 | P11: 903.1369 | Q11: 896.3088 | R11: 919.1032 | S11: 629.5232 | T11: 1243.334 | U11: 645.382 | V11: 826.4476 | W11: 687.043 | X11: 791.9838 | Y11: 810.7162 | Z11: 1267.2025 | AA11: 1157.8348 | AB11: 646.9624 | AC11: 776.2486 | AD11: 616.4304 | AE11: 813.7125 | AF11: 683.2865 | AG11: 634.7676 | AH11: 521.2551 | AI11: 589.7322 | AJ11: 331.2515 | AK11: 218.9031 | AL11: 218.5141 | AM11: 249.3229 | AN11: 255.0102 | AO11: 218.8611 | AP11: 188.7551 | AQ11: 178.1279 | AR11: 121.6148 | AS11: 57.4207 | AT11: 68.8432 | AU11: 101.3949 | AV11: 129.1894 | AW11: 228.7575 | AX11: 382.1841 | AY11: 875.9025 | AZ11: 822.7217 | BA11: 848.7929 | BB11: 1114.6629 | BC11: 856.6576 | BD11: 24.075 | BE11: 0 | BF11: 0 | BG11: 0 | BH11: 0 | BI11: 0 | BJ11: 0 | BK11: 0 | BL11: 0 | BM11: 0 | BN11: 0 | BO11: 0 | BP11: 0 | BQ11: 0 | BR11: 0 | BS11: 0 | BT11: 0 | BU11: 0 | BV11: 0 | BW11: 0 | BX11: 0 | BY11: 0 | BZ11: 0 | CA11: 0 | CB11: 0 | CC11: 0 | CD11: 0 | CE11: 0 | CF11: 0 | CG11: 0 | CH11: 0 | CI11: 0 | CJ11: 0 | CK11: 0 | CL11: 0 | CM11: 0 | CN11: 0 | CO11: 0 | CP11: 0 | CQ11: 0 | CR11: 0 | CS11: 0 | CT11: 0 | CU11: 0 | CV11: 0 | CW11: 0 | CX11: 0 | CY11: 0 | CZ11: 0 | DA11: 0 | DB11: 0 | DC11: 0 | DD11: 0 | DE11: 0 | DF11: 0 | DG11: 0 | DH11: 0 | DI11: 0 | DJ11: 0
A12: 11 | B12: 사업1 | C12: 협력2 | D12: 공사 | E12: 40238 | F12: 44165 | G12: 정규 | H12: 경영악화 | J12: 760.23 | K12: 691.204 | L12: 671.6579 | M12: 582.5274 | N12: 477.9484 | O12: 482.9776 | P12: 445.4791 | Q12: 479.6986 | R12: 493.3431 | S12: 469.617 | T12: 504.0682 | U12: 531.6697 | V12: 472.1255 | W12: 447.266 | X12: 468.9405 | Y12: 231.8968 | Z12: 306.4715 | AA12: 254.1975 | AB12: 65.8552 | AC12: 166.6124 | AD12: 109.0179 | AE12: 138.2494 | AF12: 154.1412 | AG12: 202.2905 | AH12: 251.71 | AI12: 245.3136 | AJ12: 211.2881 | AK12: 189.3968 | AL12: 261.6524 | AM12: 299.1575 | AN12: 209.685 | AO12: 203.9188 | AP12: 218.2695 | AQ12: 258.4624 | AR12: 275.9034 | AS12: 298.6181 | AT12: 337.6886 | AU12: 325.7166 | AV12: 331.4488 | AW12: 259.0333 | AX12: 386.7963 | AY12: 427.8341 | AZ12: 416.0492 | BA12: 356.3753 | BB12: 335.5525 | BC12: 337.6049 | BD12: 277.2698 | BE12: 180.1553 | BF12: 0 | BG12: 14.5445 | BH12: 46.146 | BI12: 127.1638 | BJ12: 216.1301 | BK12: 177.087 | BL12: 171.9603 | BM12: 332.8521 | BN12: 243.1742 | BO12: 145.5182 | BP12: 0 | BQ12: 0 | BR12: 0 | BS12: 0 | BT12: 0 | BU12: 0 | BV12: 0 | BW12: 0 | BX12: 0 | BY12: 0 | BZ12: 0 | CA12: 0 | CB12: 0 | CC12: 0 | CD12: 0 | CE12: 0 | CF12: 0 | CG12: 0 | CH12: 0 | CI12: 0 | CJ12: 0 | CK12: 0 | CL12: 0 | CM12: 0 | CN12: 0 | CO12: 0 | CP12: 0 | CQ12: 0 | CR12: 0 | CS12: 0 | CT12: 0 | CU12: 0 | CV12: 0 | CW12: 0 | CX12: 0 | CY12: 0 | CZ12: 0 | DA12: 0 | DB12: 0 | DC12: 0 | DD12: 0 | DE12: 0 | DF12: 0 | DG12: 0 | DH12: 0 | DI12: 0 | DJ12: 0
A13: 12 | B13: 사업1 | C13: 협력2 | D13: 공사 | E13: 42339 | F13: 44196 | G13: 정규 | H13: 경영악화 | J13: 689.491 | K13: 525.1249 | L13: 485.6069 | M13: 504.4704 | N13: 527.9372 | O13: 449.4603 | P13: 516.59 | Q13: 545.8184 | R13: 744.2537 | S13: 709.9895 | T13: 721.6346 | U13: 754.1636 | V13: 455.1791 | W13: 494.7179 | X13: 496.3256 | Y13: 351.1524 | Z13: 382.4512 | AA13: 359.0159 | AB13: 233.2599 | AC13: 420.1386 | AD13: 236.4399 | AE13: 200.053 | AF13: 97.8033 | AG13: 115.4265 | AH13: 163.1722 | AI13: 203.1131 | AJ13: 193.6809 | AK13: 214.0156 | AL13: 289.078 | AM13: 393.8579 | AN13: 325.2554 | AO13: 221.1916 | AP13: 255.638 | AQ13: 334.2351 | AR13: 367.3001 | AS13: 419.7861 | AT13: 375.6506 | AU13: 372.7719 | AV13: 300.6901 | AW13: 351.2833 | AX13: 354.0359 | AY13: 416.8502 | AZ13: 390.3922 | BA13: 383.3187 | BB13: 342.709 | BC13: 350.9396 | BD13: 214.8359 | BE13: 0 | BF13: 66.7668 | BG13: 194.9323 | BH13: 221.7323 | BI13: 298.1878 | BJ13: 325.2683 | BK13: 273.7795 | BL13: 274.7572 | BM13: 297.5164 | BN13: 352.3082 | BO13: 222.1231 | BP13: 86.672 | BQ13: 74.8262 | BR13: 0 | BS13: 0 | BT13: 0 | BU13: 0 | BV13: 0 | BW13: 0 | BX13: 0 | BY13: 0 | BZ13: 0 | CA13: 0 | CB13: 0 | CC13: 0 | CD13: 0 | CE13: 0 | CF13: 0 | CG13: 0 | CH13: 0 | CI13: 0 | CJ13: 0 | CK13: 0 | CL13: 0 | CM13: 0 | CN13: 0 | CO13: 0 | CP13: 0 | CQ13: 0 | CR13: 0 | CS13: 0 | CT13: 0 | CU13: 0 | CV13: 0 | CW13: 0 | CX13: 0 | CY13: 0 | CZ13: 0 | DA13: 0 | DB13: 0 | DC13: 0 | DD13: 0 | DE13: 0 | DF13: 0 | DG13: 0 | DH13: 0 | DI13: 0 | DJ13: 0
... A45: 44 | B45: 사업1 | C45: 협력2 | D45: 공장3 | E45: 43466 | F45: 45565 | G45: 정규 | H45: 경영악화 | J45: 0 | K45: 0 | L45: 0 | M45: 0 | N45: 0 | O45: 0 | P45: 0 | Q45: 0 | R45: 0 | S45: 0 | T45: 0 | U45: 0 | V45: 0 | W45: 0 | X45: 0 | Y45: 0 | Z45: 0 | AA45: 0 | AB45: 0 | AC45: 0 | AD45: 0 | AE45: 0 | AF45: 0 | AG45: 0 | AH45: 0 | AI45: 0 | AJ45: 0 | AK45: 0 | AL45: 0 | AM45: 0 | AN45: 0 | AO45: 0 | AP45: 0 | AQ45: 0 | AR45: 0 | AS45: 416.4396 | AT45: 379.2385 | AU45: 421.961 | AV45: 438.5306 | AW45: 424.5112 | AX45: 474.5341 | AY45: 462.1857 | AZ45: 366.6195 | BA45: 447.0526 | BB45: 456.9246 | BC45: 465.156 | BD45: 465.5624 | BE45: 451.8779 | BF45: 402.3578 | BG45: 400.28 | BH45: 355.5974 | BI45: 368.6698 | BJ45: 387.8402 | BK45: 419.379 | BL45: 266.2239 | BM45: 398.0493 | BN45: 342.3064 | BO45: 364.5191 | BP45: 302.2311 | BQ45: 351.4868 | BR45: 267.5843 | BS45: 295.9252 | BT45: 277.1343 | BU45: 320.3099 | BV45: 309.0409 | BW45: 273.6681 | BX45: 246.0446 | BY45: 246.2686 | BZ45: 383.8322 | CA45: 384.2661 | CB45: 403.0086 | CC45: 410.3826 | CD45: 356.1457 | CE45: 409.6749 | CF45: 399.991 | CG45: 408.3734 | CH45: 385.8075 | CI45: 421.1813 | CJ45: 331.7275 | CK45: 380.7886 | CL45: 344.6479 | CM45: 340.1077 | CN45: 391.6447 | CO45: 443.2931 | CP45: 436.1004 | CQ45: 452.6743 | CR45: 137.6295 | CS45: 141.8505 | CT45: 653.4427 | CU45: 417.0447 | CV45: 520.9727 | CW45: 329.2368 | CX45: 384.8172 | CY45: 406.7133 | CZ45: 456.3217 | DA45: 367.2784 | DB45: 335.8787 | DC45: 346.094 | DD45: 621.7671 | DE45: 623.3914 | DF45: 342.7519 | DG45: 378.8741 | DH45: 361.157 | DI45: 266.6047 | DJ45: 0.5879
A46: 45 | B46: 사업1 | C46: 협력2 | D46: 지원 | E46: 34790 | F46: - | G46: 정규 | H46: 거래중 | J46: 480.904 | K46: 574.4518 | L46: 554.3706 | M46: 434.1285 | N46: 534.6191 | O46: 453.6603 | P46: 480.9095 | Q46: 542.6227 | R46: 683.0259 | S46: 664.979 | T46: 699.2854 | U46: 496.479 | V46: 444.4653 | W46: 477.7764 | X46: 449.0727 | Y46: 299.1105 | Z46: 446.807 | AA46: 235.9667 | AB46: 295.5371 | AC46: 368.9708 | AD46: 199.5302 | AE46: 226.3235 | AF46: 189.706 | AG46: 221.9229 | AH46: 113.9535 | AI46: 149.2833 | AJ46: 121.9844 | AK46: 147.5199 | AL46: 245.8618 | AM46: 321.4797 | AN46: 173.4016 | AO46: 197.6677 | AP46: 319.7083 | AQ46: 349.2966 | AR46: 295.6235 | AS46: 279.1591 | AT46: 289.1724 | AU46: 283.9888 | AV46: 267.3162 | AW46: 341.3982 | AX46: 299.0184 | AY46: 329.0852 | AZ46: 304.9958 | BA46: 274.0642 | BB46: 230.1214 | BC46: 284.663 | BD46: 722.7831 | BE46: 696.3031 | BF46: 753.9443 | BG46: 767.6233 | BH46: 786.3663 | BI46: 659.7731 | BJ46: 1072.6239 | BK46: 540.598 | BL46: 492.4525 | BM46: 519.0564 | BN46: 533.7354 | BO46: 582.9641 | BP46: 588.6937 | BQ46: 581.5747 | BR46: 510.5518 | BS46: 637.1808 | BT46: 548.7649 | BU46: 527.8332 | BV46: 526.9631 | BW46: 496.9518 | BX46: 396.174 | BY46: 385.4044 | BZ46: 460.0582 | CA46: 505.6252 | CB46: 480.96 | CC46: 406.3506 | CD46: 327.442 | CE46: 416.6682 | CF46: 407.4378 | CG46: 461.2665 | CH46: 364.9062 | CI46: 365.3897 | CJ46: 322.2069 | CK46: 347.831 | CL46: 384.5856 | CM46: 435.5699 | CN46: 499.4781 | CO46: 422.8455 | CP46: 517.5719 | CQ46: 421.2645 | CR46: 400.6162 | CS46: 430.4043 | CT46: 464.779 | CU46: 523.5469 | CV46: 539.963 | CW46: 597.0765 | CX46: 509.2038 | CY46: 934.6333 | CZ46: 707.1948 | DA46: 676.2828 | DB46: 641.8009 | DC46: 821.3047 | DD46: 773.258 | DE46: 893.1071 | DF46: 909.683 | DG46: 975.6202 | DH46: 792.8682 | DI46: 794.9447 | DJ46: 879.929
A47: 46 | B47: 사업1 | C47: 협력2 | D47: 공장3 | E47: 36990 | F47: - | G47: 정규 | H47: 거래중 | J47: 541.983 | K47: 413.7543 | L47: 449.4759 | M47: 473.1409 | N47: 450.6369 | O47: 417.2359 | P47: 377.0223 | Q47: 412.8358 | R47: 428.4215 | S47: 459.5665 | T47: 438.1415 | U47: 357.788 | V47: 345.1104 | W47: 551.4542 | X47: 546.972 | Y47: 420.2231 | Z47: 506.7586 | AA47: 294.2362 | AB47: 292.2378 | AC47: 273.8317 | AD47: 188.2642 | AE47: 289.4164 | AF47: 285.0486 | AG47: 369.3771 | AH47: 352.9165 | AI47: 445.9082 | AJ47: 455.0199 | AK47: 453.2209 | AL47: 442.0675 | AM47: 394.8066 | AN47: 151.7772 | AO47: 545.042 | AP47: 450.0093 | AQ47: 610.9046 | AR47: 485.751 | AS47: 779.8571 | AT47: 607.3889 | AU47: 860.9484 | AV47: 931.0961 | AW47: 1009.9666 | AX47: 963.0281 | AY47: 1097.3324 | AZ47: 888.6029 | BA47: 1031.8065 | BB47: 1200.7948 | BC47: 1138.109 | BD47: 1104.3442 | BE47: 1042.7861 | BF47: 1169.3248 | BG47: 1239.3636 | BH47: 1030.6308 | BI47: 1061.0687 | BJ47: 1116.0518 | BK47: 1138.2434 | BL47: 882.2366 | BM47: 956.166 | BN47: 1038.7085 | BO47: 1114.5071 | BP47: 1130.2683 | BQ47: 1034.9004 | BR47: 1056.1155 | BS47: 1133.4994 | BT47: 1272.8795 | BU47: 1003.7408 | BV47: 1135.0675 | BW47: 1185.0162 | BX47: 885.7819 | BY47: 990.0115 | BZ47: 1045.4432 | CA47: 721.7127 | CB47: 754.5075 | CC47: 762.2261 | CD47: 670.8525 | CE47: 692.4727 | CF47: 675.6162 | CG47: 659.3432 | CH47: 700.9657 | CI47: 689.1297 | CJ47: 615.8578 | CK47: 633.2921 | CL47: 758.9887 | CM47: 692.9635 | CN47: 761.4763 | CO47: 703.7825 | CP47: 765.4464 | CQ47: 786.1315 | CR47: 304.637 | CS47: 426.5932 | CT47: 1127.9186 | CU47: 928.1734 | CV47: 700.2796 | CW47: 921.1317 | CX47: 826.9873 | CY47: 1000.9592 | CZ47: 874.5 | DA47: 987.0008 | DB47: 611.6876 | DC47: 842.2869 | DD47: 721.7557 | DE47: 802.1696 | DF47: 640.3323 | DG47: 732.6623 | DH47: 526.084 | DI47: 607.0668 | DJ47: 657.0416
A48: 47 | B48: 사업2 | C48: 협력3 | D48: 외장2 | E48: 37168 | F48: - | G48: 정규 | H48: 거래중 | J48: 951.766 | K48: 1459.053 | L48: 1310.647 | M48: 1513.1848 | N48: 1402.4995 | O48: 1358.9145 | P48: 1490.7013 | Q48: 1319.3329 | R48: 1453.3572 | S48: 1612.069 | T48: 1658.7498 | U48: 1508.3066 | V48: 1274.828 | W48: 2406.9155 | X48: 1807.253 | Y48: 706.4944 | Z48: 1048.5402 | AA48: 1231.9067 | AB48: 900.4133 | AC48: 974.2654 | AD48: 685.1761 | AE48: 863.2109 | AF48: 671.0926 | AG48: 563.1275 | AH48: 393.0674 | AI48: 252.49 | AJ48: 320.1203 | AK48: 354.1209 | AL48: 331.2764 | AM48: 300.8588 | AN48: 225.0738 | AO48: 293.7255 | AP48: 334.4021 | AQ48: 407.7767 | AR48: 437.4917 | AS48: 524.0601 | AT48: 367.1407 | AU48: 598.8229 | AV48: 625.1999 | AW48: 712.5988 | AX48: 570.1444 | AY48: 756.9164 | AZ48: 556.9449 | BA48: 697.5865 | BB48: 912.5288 | BC48: 960.4273 | BD48: 924.8983 | BE48: 824.1259 | BF48: 828.921 | BG48: 864.7848 | BH48: 863.0577 | BI48: 824.2146 | BJ48: 806.9601 | BK48: 699.6019 | BL48: 626.9353 | BM48: 737.6315 | BN48: 738.1138 | BO48: 829.6991 | BP48: 976.0677 | BQ48: 792.8818 | BR48: 652.2446 | BS48: 835.439 | BT48: 878.2122 | BU48: 771.7101 | BV48: 798.9522 | BW48: 731.6941 | BX48: 575.3062 | BY48: 821.9435 | BZ48: 919.1535 | CA48: 641.4053 | CB48: 514.8801 | CC48: 530.0954 | CD48: 487.4531 | CE48: 571.4603 | CF48: 552.8229 | CG48: 511.6311 | CH48: 530.5066 | CI48: 541.7939 | CJ48: 326.805 | CK48: 349.1572 | CL48: 374.3691 | CM48: 384.2072 | CN48: 353.0564 | CO48: 338.5751 | CP48: 337.2242 | CQ48: 416.8116 | CR48: 387.7116 | CS48: 356.7971 | CT48: 407.432 | CU48: 406.0206 | CV48: 399.6844 | CW48: 436.7572 | CX48: 449.9223 | CY48: 446.6486 | CZ48: 457.8584 | DA48: 457.0688 | DB48: 442.1978 | DC48: 652.313 | DD48: 620.1138 | DE48: 657.7905 | DF48: 576.0617 | DG48: 567.3543 | DH48: 532.2734 | DI48: 558.3521 | DJ48: 614.0493
A49: 48 | B49: 사업1 | C49: 협력3 | D49: 외장3 | E49: 37469 | F49: - | G49: 정규 | H49: 거래중 | J49: 744.657 | K49: 958.42 | L49: 1648.4708 | M49: 1626.5218 | N49: 1476.5011 | O49: 1596.1604 | P49: 1550.9892 | Q49: 1162.4407 | R49: 1594.3459 | S49: 2635.3358 | T49: 2470.8951 | U49: 1883.8388 | V49: 1824.9103 | W49: 2172.5041 | X49: 2087.7315 | Y49: 1231.2708 | Z49: 1421.8552 | AA49: 1285.4756 | AB49: 1088.5503 | AC49: 1520.4685 | AD49: 1007.2558 | AE49: 906.0737 | AF49: 658.3873 | AG49: 499.3651 | AH49: 283.3921 | AI49: 382.307 | AJ49: 332.434 | AK49: 365.0731 | AL49: 410.3094 | AM49: 429.1464 | AN49: 324.3054 | AO49: 420.7192 | AP49: 537.9326 | AQ49: 432.8733 | AR49: 519.9663 | AS49: 476.6572 | AT49: 424.6112 | AU49: 546.045 | AV49: 536.8664 | AW49: 606.5945 | AX49: 747.1111 | AY49: 736.9788 | AZ49: 638.1855 | BA49: 688.7926 | BB49: 731.0696 | BC49: 769.3878 | BD49: 863.4366 | BE49: 801.8997 | BF49: 830.9037 | BG49: 939.0048 | BH49: 952.3331 | BI49: 915.3025 | BJ49: 992.0759 | BK49: 1267.7112 | BL49: 1007.3134 | BM49: 1131.8085 | BN49: 1137.3498 | BO49: 1011.764 | BP49: 900.5747 | BQ49: 851.43 | BR49: 774.663 | BS49: 858.9664 | BT49: 938.4964 | BU49: 951.742 | BV49: 1050.682 | BW49: 1149.0617 | BX49: 956.8831 | BY49: 1422.6443 | BZ49: 904.9794 | CA49: 869.8019 | CB49: 823.5894 | CC49: 911.197 | CD49: 812.0594 | CE49: 853.1933 | CF49: 1200.8118 | CG49: 911.6722 | CH49: 782.3528 | CI49: 640.6414 | CJ49: 583.6672 | CK49: 470.8393 | CL49: 522.3373 | CM49: 708.371 | CN49: 683.2917 | CO49: 639.1452 | CP49: 822.341 | CQ49: 863.0804 | CR49: 794.4229 | CS49: 819.2159 | CT49: 904.3757 | CU49: 889.8786 | CV49: 808.0574 | CW49: 669.7747 | CX49: 871.6472 | CY49: 798.4613 | CZ49: 852.9644 | DA49: 778.1259 | DB49: 839.7921 | DC49: 889.2533 | DD49: 972.4101 | DE49: 1201.0304 | DF49: 1178.3514 | DG49: 1160.9767 | DH49: 995.0269 | DI49: 1103.6515 | DJ49: 1211.4333
A50: 49 | B50: 사업1 | C50: 협력2 | D50: 공장3 | E50: 37623 | F50: - | G50: 정규 | H50: 거래중 | J50: 472.005 | K50: 473.0388 | L50: 416.7014 | M50: 491.9269 | N50: 515.6083 | O50: 442.0767 | P50: 473.7494 | Q50: 436.3707 | R50: 559.6088 | S50: 532.1906 | T50: 512.6803 | U50: 495.1067 | V50: 435.3805 | W50: 425.4192 | X50: 447.7253 | Y50: 259.7332 | Z50: 343.6806 | AA50: 332.7477 | AB50: 223.0569 | AC50: 358.1547 | AD50: 180.8808 | AE50: 167.0866 | AF50: 116.5855 | AG50: 147.2376 | AH50: 141.3252 | AI50: 153.4521 | AJ50: 194.1634 | AK50: 192.5079 | AL50: 277.2427 | AM50: 335.7404 | AN50: 301.2043 | AO50: 189.36 | AP50: 221.1382 | AQ50: 249.6472 | AR50: 283.6166 | AS50: 397.7689 | AT50: 354.2059 | AU50: 350.1785 | AV50: 261.9086 | AW50: 309.9604 | AX50: 386.048 | AY50: 401.4758 | AZ50: 357.6067 | BA50: 283.9506 | BB50: 285.0443 | BC50: 324.4239 | BD50: 287.6546 | BE50: 476.6252 | BF50: 503.4488 | BG50: 475.8848 | BH50: 533.5579 | BI50: 447.2664 | BJ50: 585.9171 | BK50: 565.297 | BL50: 413.0705 | BM50: 471.6332 | BN50: 458.0519 | BO50: 412.1761 | BP50: 446.7496 | BQ50: 409.5312 | BR50: 357.8146 | BS50: 435.9828 | BT50: 284.9468 | BU50: 350.549 | BV50: 378.755 | BW50: 331.9835 | BX50: 237.8313 | BY50: 331.1769 | BZ50: 405.3305 | CA50: 395.6263 | CB50: 374.4486 | CC50: 381.548 | CD50: 392.5066 | CE50: 444.5415 | CF50: 432.0566 | CG50: 408.3841 | CH50: 439.6924 | CI50: 408.3403 | CJ50: 331.8197 | CK50: 381.1621 | CL50: 344.7416 | CM50: 558.8176 | CN50: 518.2759 | CO50: 477.3683 | CP50: 530.6911 | CQ50: 631.2197 | CR50: 287.0932 | CS50: 295.3347 | CT50: 1021.362 | CU50: 535.4032 | CV50: 538.1042 | CW50: 659.9312 | CX50: 460.8938 | CY50: 542.5645 | CZ50: 537.2749 | DA50: 544.6981 | DB50: 424.2931 | DC50: 523.8874 | DD50: 481.5806 | DE50: 509.3661 | DF50: 388.3469 | DG50: 578.5723 | DH50: 301.4124 | DI50: 364.756 | DJ50: 389.7591
A51: 50 | B51: 사업1 | C51: 협력1 | D51: 라인2 | E51: 37712 | F51: - | G51: 정규 | H51: 거래중 | J51: 332.179 | K51: 598.0199 | L51: 738.5643 | M51: 800.7986 | N51: 864.8375 | O51: 931.0451 | P51: 682.6257 | Q51: 644.103 | R51: 815.7518 | S51: 910.9592 | T51: 926.0993 | U51: 859.2283 | V51: 758.9107 | W51: 905.5894 | X51: 746.8998 | Y51: 675.1342 | Z51: 665.5115 | AA51: 562.2928 | AB51: 524.2019 | AC51: 757.6363 | AD51: 584.2088 | AE51: 621.9257 | AF51: 289.5577 | AG51: 348.588 | AH51: 138.1043 | AI51: 193.9873 | AJ51: 248.7289 | AK51: 289.0335 | AL51: 291.9307 | AM51: 295.9102 | AN51: 214.1506 | AO51: 273.8532 | AP51: 297.6697 | AQ51: 339.5891 | AR51: 239.5579 | AS51: 523.5922 | AT51: 432.363 | AU51: 699.2099 | AV51: 726.3237 | AW51: 719.8805 | AX51: 675.2428 | AY51: 695.8963 | AZ51: 565.3774 | BA51: 582.4292 | BB51: 721.2507 | BC51: 681.659 | BD51: 702.0718 | BE51: 770.6825 | BF51: 652.5141 | BG51: 600.4783 | BH51: 697.623 | BI51: 637.9761 | BJ51: 641.5286 | BK51: 659.4647 | BL51: 472.1859 | BM51: 601.092 | BN51: 501.424 | BO51: 396.7615 | BP51: 370.2277 | BQ51: 238.6918 | BR51: 227.5948 | BS51: 244.4394 | BT51: 284.4241 | BU51: 257.4517 | BV51: 292.5929 | BW51: 258.3972 | BX51: 194.9294 | BY51: 253.5572 | BZ51: 304.0862 | CA51: 316.5293 | CB51: 344.4082 | CC51: 304.5314 | CD51: 253.7863 | CE51: 284.2811 | CF51: 272.8345 | CG51: 258.2131 | CH51: 235.0581 | CI51: 265.5234 | CJ51: 251.7172 | CK51: 230.9691 | CL51: 234.0194 | CM51: 277.4982 | CN51: 325.1543 | CO51: 246.6646 | CP51: 246.4388 | CQ51: 293.5141 | CR51: 240.3581 | CS51: 288.4062 | CT51: 348.8698 | CU51: 329.1067 | CV51: 279.6128 | CW51: 265.5869 | CX51: 299.3372 | CY51: 389.9686 | CZ51: 358.2889 | DA51: 427.9411 | DB51: 355.7605 | DC51: 479.4313 | DD51: 421.4374 | DE51: 443.3215 | DF51: 413.1214 | DG51: 421.7008 | DH51: 357.1332 | DI51: 343.6332 | DJ51: 375.4869
A52: 51 | B52: 사업1 | C52: 협력2 | D52: 공장3 | E52: 38033 | F52: - | G52: 정규 | H52: 거래중 | J52: 528.271 | K52: 445.9987 | L52: 412.1607 | M52: 441.7252 | N52: 441.0183 | O52: 403.3004 | P52: 386.712 | Q52: 358.0543 | R52: 389.5295 | S52: 416.8626 | T52: 421.8347 | U52: 296.2928 | V52: 264.3617 | W52: 412.6918 | X52: 378.3109 | Y52: 340.5996 | Z52: 461.9556 | AA52: 234.413 | AB52: 178.5082 | AC52: 299.8293 | AD52: 265.3955 | AE52: 349.6375 | AF52: 337.4113 | AG52: 384.9684 | AH52: 313.8394 | AI52: 468.2238 | AJ52: 460.1382 | AK52: 467.6085 | AL52: 482.9573 | AM52: 512.3135 | AN52: 420.1595 | AO52: 441.3421 | AP52: 522.558 | AQ52: 454.0561 | AR52: 471.8359 | AS52: 589.8628 | AT52: 358.5666 | AU52: 378.9506 | AV52: 401.2229 | AW52: 429.9187 | AX52: 410.4559 | AY52: 398.723 | AZ52: 367.0533 | BA52: 421.2229 | BB52: 458.8534 | BC52: 454.9623 | BD52: 490.6206 | BE52: 443.6615 | BF52: 430.9241 | BG52: 447.2194 | BH52: 396.6685 | BI52: 409.7269 | BJ52: 451.2179 | BK52: 433.6505 | BL52: 334.8862 | BM52: 429.0754 | BN52: 373.2713 | BO52: 376.302 | BP52: 322.3935 | BQ52: 395.1078 | BR52: 330.5634 | BS52: 350.6703 | BT52: 358.5432 | BU52: 381.0533 | BV52: 385.2026 | BW52: 344.9614 | BX52: 291.9767 | BY52: 322.4918 | BZ52: 421.5091 | CA52: 427.609 | CB52: 439.5855 | CC52: 430.9676 | CD52: 377.0295 | CE52: 408.697 | CF52: 407.7444 | CG52: 386.584 | CH52: 406.9538 | CI52: 390.6547 | CJ52: 290.9416 | CK52: 351.7875 | CL52: 346.4647 | CM52: 445.0861 | CN52: 424.8432 | CO52: 431.7519 | CP52: 476.1546 | CQ52: 530.275 | CR52: 293.308 | CS52: 254.0507 | CT52: 735.8097 | CU52: 564.3528 | CV52: 439.9142 | CW52: 633.0412 | CX52: 618.1351 | CY52: 570.6125 | CZ52: 547.1756 | DA52: 527.1403 | DB52: 399.3508 | DC52: 454.1004 | DD52: 429.7567 | DE52: 399.9084 | DF52: 414.6039 | DG52: 486.466 | DH52: 374.1055 | DI52: 317.0692 | DJ52: 438.2434
A53: 52 | B53: 사업1 | C53: 협력1 | D53: 내장1 | E53: 39022 | F53: - | G53: 정규 | H53: 거래중 | J53: 312.008 | K53: 303.3208 | L53: 395.8229 | M53: 379.0732 | N53: 388.0264 | O53: 357.3512 | P53: 327.3722 | Q53: 332.0179 | R53: 418.4813 | S53: 415.5085 | T53: 426.5993 | U53: 420.9815 | V53: 531.7382 | W53: 583.9357 | X53: 620.7286 | Y53: 528.8648 | Z53: 628.1036 | AA53: 543.1949 | AB53: 352.8022 | AC53: 604.1491 | AD53: 431.99 | AE53: 480.1721 | AF53: 449.5874 | AG53: 459.2635 | AH53: 325.2267 | AI53: 405.2933 | AJ53: 400.4809 | AK53: 414.4822 | AL53: 380.1356 | AM53: 433.9923 | AN53: 237.0547 | AO53: 341.0621 | AP53: 337.2297 | AQ53: 357.1423 | AR53: 325.4225 | AS53: 386.2366 | AT53: 284.6201 | AU53: 358.2187 | AV53: 404.0733 | AW53: 418.083 | AX53: 376.6448 | AY53: 499.3239 | AZ53: 386.9483 | BA53: 387.2735 | BB53: 459.6726 | BC53: 437.9813 | BD53: 509.8309 | BE53: 455.2985 | BF53: 534.4001 | BG53: 639.9905 | BH53: 685.7118 | BI53: 766.5562 | BJ53: 897.7787 | BK53: 914.4029 | BL53: 776.5872 | BM53: 832.4177 | BN53: 824.5426 | BO53: 746.8125 | BP53: 749.2918 | BQ53: 746.1271 | BR53: 695.1114 | BS53: 832.6382 | BT53: 671.9631 | BU53: 483.8584 | BV53: 516.2504 | BW53: 521.4123 | BX53: 403.1595 | BY53: 411.8807 | BZ53: 446.2088 | CA53: 467.9323 | CB53: 492.0107 | CC53: 492.6862 | CD53: 459.3258 | CE53: 539.8275 | CF53: 475.8087 | CG53: 456.9868 | CH53: 389.5176 | CI53: 326.416 | CJ53: 262.4893 | CK53: 308.187 | CL53: 366.7192 | CM53: 408.0609 | CN53: 429.8199 | CO53: 398.7419 | CP53: 381.6343 | CQ53: 457.5293 | CR53: 489.1839 | CS53: 507.9971 | CT53: 484.0026 | CU53: 489.4715 | CV53: 398.7778 | CW53: 492.0073 | CX53: 566.5198 | CY53: 600.5131 | CZ53: 549.108 | DA53: 646.84 | DB53: 565.4894 | DC53: 732.1009 | DD53: 695.4433 | DE53: 661.0362 | DF53: 622.7292 | DG53: 658.4169 | DH53: 425.5576 | DI53: 511.1114 | DJ53: 684.9934
A54: 53 | B54: 사업1 | C54: 협력1 | D54: 외장1 | E54: 39188 | F54: - | G54: 정규 | H54: 거래중 | J54: 521.777 | K54: 561.7561 | L54: 622.586 | M54: 458.7157 | N54: 399.2508 | O54: 434.4314 | P54: 300.485 | Q54: 453.5694 | R54: 376.1572 | S54: 394.952 | T54: 368.6337 | U54: 350.7439 | V54: 306.6421 | W54: 301.1511 | X54: 285.0874 | Y54: 204.4215 | Z54: 364.657 | AA54: 271.7308 | AB54: 213.6546 | AC54: 396.5394 | AD54: 354.202 | AE54: 393.5567 | AF54: 380.4113 | AG54: 345.3488 | AH54: 374.797 | AI54: 410.6051 | AJ54: 366.6784 | AK54: 378.6546 | AL54: 339.2446 | AM54: 386.8506 | AN54: 303.761 | AO54: 262.106 | AP54: 294.3178 | AQ54: 509.5023 | AR54: 544.0789 | AS54: 719.9293 | AT54: 685.5057 | AU54: 956.2317 | AV54: 1061.1163 | AW54: 1077.9477 | AX54: 975.67 | AY54: 1002.7367 | AZ54: 839.3184 | BA54: 930.9285 | BB54: 854.6094 | BC54: 985.5386 | BD54: 825.9984 | BE54: 872.9522 | BF54: 791.3857 | BG54: 1025.3484 | BH54: 903.5529 | BI54: 812.8693 | BJ54: 889.0262 | BK54: 880.5885 | BL54: 569.6481 | BM54: 709.2135 | BN54: 746.6289 | BO54: 734.4441 | BP54: 525.2679 | BQ54: 620.7896 | BR54: 642.3505 | BS54: 776.788 | BT54: 716.8862 | BU54: 603.7804 | BV54: 701.8967 | BW54: 657.3502 | BX54: 502.6372 | BY54: 585.0479 | BZ54: 602.4282 | CA54: 817.9395 | CB54: 879.4937 | CC54: 806.9625 | CD54: 680.6806 | CE54: 767.5022 | CF54: 747.5316 | CG54: 792.118 | CH54: 771.8096 | CI54: 809.7178 | CJ54: 706.6555 | CK54: 714.6517 | CL54: 706.9761 | CM54: 748.069 | CN54: 770.9628 | CO54: 702.1703 | CP54: 784.2165 | CQ54: 882.7906 | CR54: 800.4993 | CS54: 826.1664 | CT54: 855.4582 | CU54: 848.504 | CV54: 730.0823 | CW54: 771.7975 | CX54: 1036.7901 | CY54: 1153.0382 | CZ54: 1091.9498 | DA54: 1061.7906 | DB54: 945.8037 | DC54: 1153.1846 | DD54: 1088.3579 | DE54: 1118.7375 | DF54: 1039.1196 | DG54: 1130.3914 | DH54: 897.9884 | DI54: 876.5067 | DJ54: 968.9775
A55: 54 | B55: 사업1 | C55: 협력1 | D55: 라인2 | E55: 39479 | F55: - | G55: 정규 | H55: 거래중 | J55: 1123.257 | K55: 1496.3628 | L55: 1617.9747 | M55: 1799.3714 | N55: 1568.2737 | O55: 1370.4234 | P55: 774.6975 | Q55: 646.735 | R55: 944.3649 | S55: 872.1688 | T55: 900.3455 | U55: 863.2085 | V55: 732.1941 | W55: 807.683 | X55: 714.064 | Y55: 440.2979 | Z55: 505.834 | AA55: 423.1646 | AB55: 433.3013 | AC55: 670.7293 | AD55: 536.6248 | AE55: 518.3378 | AF55: 339.8934 | AG55: 311.8126 | AH55: 194.5459 | AI55: 262.1097 | AJ55: 283.0805 | AK55: 289.2558 | AL55: 266.0941 | AM55: 200.1566 | AN55: 114.7794 | AO55: 143.6686 | AP55: 163.7289 | AQ55: 172.3735 | AR55: 159.0683 | AS55: 199.0338 | AT55: 253.0586 | AU55: 445.7119 | AV55: 462.6199 | AW55: 586.9412 | AX55: 571.8455 | AY55: 628.5468 | AZ55: 428.0838 | BA55: 415.6467 | BB55: 538.9107 | BC55: 609.4624 | BD55: 778.7971 | BE55: 681.0549 | BF55: 818.2311 | BG55: 765.9565 | BH55: 708.9673 | BI55: 592.2418 | BJ55: 557.6009 | BK55: 567.8754 | BL55: 388.5223 | BM55: 549.3213 | BN55: 632.7956 | BO55: 606.3121 | BP55: 535.4735 | BQ55: 508.0881 | BR55: 433.4126 | BS55: 452.5344 | BT55: 404.84 | BU55: 362.4153 | BV55: 421.5534 | BW55: 412.611 | BX55: 285.7592 | BY55: 332.6011 | BZ55: 296.4552 | CA55: 360.3238 | CB55: 396.4243 | CC55: 404.7432 | CD55: 352.6709 | CE55: 419.0513 | CF55: 330.6515 | CG55: 373.69 | CH55: 368.7817 | CI55: 332.5147 | CJ55: 305.1916 | CK55: 314.194 | CL55: 386.4954 | CM55: 407.0028 | CN55: 377.8211 | CO55: 325.1577 | CP55: 386.3353 | CQ55: 475.1771 | CR55: 462.9749 | CS55: 537.1222 | CT55: 528.4743 | CU55: 534.9498 | CV55: 474.2193 | CW55: 483.2314 | CX55: 576.649 | CY55: 673.0789 | CZ55: 628.7368 | DA55: 727.6371 | DB55: 671.075 | DC55: 881.354 | DD55: 857.5758 | DE55: 792.9879 | DF55: 723.7191 | DG55: 825.6116 | DH55: 619.6649 | DI55: 675.1887 | DJ55: 869.9333
A56: 55 | B56: 사업1 | C56: 협력3 | D56: 외장3 | E56: 39615 | F56: - | G56: 정규 | H56: 거래중 | J56: 396.101 | K56: 613.147 | L56: 590.3615 | M56: 542.9353 | N56: 469.2573 | O56: 697.9921 | P56: 686.256 | Q56: 651.0434 | R56: 808.94 | S56: 972.6886 | T56: 1073.3598 | U56: 1115.8377 | V56: 884.155 | W56: 1141.7554 | X56: 848.8943 | Y56: 756.0423 | Z56: 657.1418 | AA56: 465.5898 | AB56: 401.6708 | AC56: 739.3525 | AD56: 414.9381 | AE56: 506.484 | AF56: 487.3132 | AG56: 352.3814 | AH56: 343.9828 | AI56: 415.2738 | AJ56: 525.7276 | AK56: 470.1772 | AL56: 487.2144 | AM56: 459.9361 | AN56: 291.9203 | AO56: 394.6054 | AP56: 457.3989 | AQ56: 408.0101 | AR56: 538.3926 | AS56: 523.6305 | AT56: 449.0287 | AU56: 493.1226 | AV56: 533.5106 | AW56: 591.9278 | AX56: 726.5899 | AY56: 766.1982 | AZ56: 705.563 | BA56: 697.3343 | BB56: 696.319 | BC56: 785.4781 | BD56: 1032.7704 | BE56: 753.031 | BF56: 907.4168 | BG56: 1174.3961 | BH56: 1151.2329 | BI56: 1303.1033 | BJ56: 1259.9167 | BK56: 1343.1835 | BL56: 1139.6046 | BM56: 1261.2174 | BN56: 1382.9819 | BO56: 1329.8094 | BP56: 1172.5615 | BQ56: 1014.2812 | BR56: 896.226 | BS56: 889.8932 | BT56: 937.39 | BU56: 963.412 | BV56: 1020.3575 | BW56: 1100.0679 | BX56: 975.9862 | BY56: 923.6674 | BZ56: 908.8593 | CA56: 886.0426 | CB56: 804.0795 | CC56: 930.0947 | CD56: 807.7541 | CE56: 855.5081 | CF56: 903.2425 | CG56: 892.1411 | CH56: 841.1941 | CI56: 717.5106 | CJ56: 516.0657 | CK56: 485.9243 | CL56: 559.4819 | CM56: 776.6821 | CN56: 734.1751 | CO56: 649.8767 | CP56: 842.9369 | CQ56: 881.0729 | CR56: 859.3357 | CS56: 841.3555 | CT56: 953.1129 | CU56: 948.1131 | CV56: 831.9079 | CW56: 697.076 | CX56: 963.083 | CY56: 879.0504 | CZ56: 919.3132 | DA56: 937.9069 | DB56: 818.9961 | DC56: 876.6093 | DD56: 1026.2463 | DE56: 991.2545 | DF56: 1074.8033 | DG56: 1094.4403 | DH56: 1015.0388 | DI56: 1056.0822 | DJ56: 1143.3413
A57: 56 | B57: 사업1 | C57: 협력2 | D57: 공장2 | E57: 40330 | F57: - | G57: 정규 | H57: 거래중 | J57: 388.811 | K57: 411.0007 | L57: 379.97 | M57: 271.4739 | N57: 345.7834 | O57: 331.6633 | P57: 288.2674 | Q57: 335.8315 | R57: 381.1745 | S57: 360.6707 | T57: 339.6455 | U57: 259.5209 | V57: 254.1488 | W57: 248.8502 | X57: 220.6335 | Y57: 228.5017 | Z57: 246.8832 | AA57: 116.7898 | AB57: 92.5849 | AC57: 143.0496 | AD57: 134.2385 | AE57: 185.8209 | AF57: 151.1111 | AG57: 249.8698 | AH57: 199.293 | AI57: 274.6759 | AJ57: 252.1139 | AK57: 292.3244 | AL57: 247.7025 | AM57: 269.0648 | AN57: 249.5626 | AO57: 270.3321 | AP57: 317.0292 | AQ57: 341.6337 | AR57: 351.8973 | AS57: 318.4656 | AT57: 307.2779 | AU57: 366.0024 | AV57: 454.4543 | AW57: 497.7867 | AX57: 543.3399 | AY57: 576.0977 | AZ57: 509.8525 | BA57: 520.4584 | BB57: 526.4229 | BC57: 500.9214 | BD57: 491.0145 | BE57: 521.679 | BF57: 511.3585 | BG57: 593.2351 | BH57: 541.4548 | BI57: 553.9085 | BJ57: 603.2703 | BK57: 527.9159 | BL57: 432.2095 | BM57: 560.9976 | BN57: 552.523 | BO57: 644.4926 | BP57: 563.1738 | BQ57: 571.7639 | BR57: 488.3894 | BS57: 588.3266 | BT57: 586.662 | BU57: 572.0891 | BV57: 614.9245 | BW57: 595.5502 | BX57: 515.6036 | BY57: 548.81 | BZ57: 683.9408 | CA57: 729.137 | CB57: 710.6352 | CC57: 716.9104 | CD57: 636.7341 | CE57: 685.8304 | CF57: 678.9905 | CG57: 720.2632 | CH57: 714.9419 | CI57: 713.9613 | CJ57: 624.1573 | CK57: 646.9058 | CL57: 668.7151 | CM57: 668.7815 | CN57: 718.8852 | CO57: 787.7166 | CP57: 715.8934 | CQ57: 766.9866 | CR57: 340.9789 | CS57: 559.0532 | CT57: 1100.2668 | CU57: 752.5124 | CV57: 735.0624 | CW57: 806.6346 | CX57: 820.0357 | CY57: 906.7422 | CZ57: 785.9339 | DA57: 905.0608 | DB57: 705.9364 | DC57: 813.5524 | DD57: 817.2586 | DE57: 795.8387 | DF57: 680.6455 | DG57: 757.4343 | DH57: 579.2978 | DI57: 538.7278 | DJ57: 646.546
... A128: 127 | B128: 사업1 | C128: 협력1 | D128: 외장1 | E128: 45597 | F128: - | G128: 정규 | H128: 거래중 | J128: 0 | K128: 0 | L128: 0 | M128: 0 | N128: 0 | O128: 0 | P128: 0 | Q128: 0 | R128: 0 | S128: 0 | T128: 0 | U128: 0 | V128: 0 | W128: 0 | X128: 0 | Y128: 0 | Z128: 0 | AA128: 0 | AB128: 0 | AC128: 0 | AD128: 0 | AE128: 0 | AF128: 0 | AG128: 0 | AH128: 0 | AI128: 0 | AJ128: 0 | AK128: 0 | AL128: 0 | AM128: 0 | AN128: 0 | AO128: 0 | AP128: 0 | AQ128: 0 | AR128: 0 | AS128: 0 | AT128: 0 | AU128: 0 | AV128: 0 | AW128: 0 | AX128: 0 | AY128: 0 | AZ128: 0 | BA128: 0 | BB128: 0 | BC128: 0 | BD128: 0 | BE128: 0 | BF128: 0 | BG128: 0 | BH128: 0 | BI128: 0 | BJ128: 0 | BK128: 0 | BL128: 0 | BM128: 0 | BN128: 0 | BO128: 0 | BP128: 0 | BQ128: 0 | BR128: 0 | BS128: 0 | BT128: 0 | BU128: 0 | BV128: 0 | BW128: 0 | BX128: 0 | BY128: 0 | BZ128: 0 | CA128: 0 | CB128: 0 | CC128: 0 | CD128: 0 | CE128: 0 | CF128: 0 | CG128: 0 | CH128: 0 | CI128: 0 | CJ128: 0 | CK128: 0 | CL128: 0 | CM128: 0 | CN128: 0 | CO128: 0 | CP128: 0 | CQ128: 0 | CR128: 0 | CS128: 0 | CT128: 0 | CU128: 0 | CV128: 0 | CW128: 0 | CX128: 0 | CY128: 0 | CZ128: 0 | DA128: 0 | DB128: 0 | DC128: 0 | DD128: 0 | DE128: 0 | DF128: 0 | DG128: 0 | DH128: 0 | DI128: 0 | DJ128: 0

Sheet 공수능률
A1: No. | B1: 구분 | C1: 중구분 | D1: 소구분 | E1: 당사투입일 | F1: 계약종결일 | G1: 협력사구분 | H1: 계약종결사유 | J1: 42411 | K1: 42441 | L1: 42471 | M1: 42501 | N1: 42531 | O1: 42561 | P1: 42591 | Q1: 42621 | R1: 42651 | S1: 42681 | T1: 42711 | U1: 42741 | V1: 42771 | W1: 42801 | X1: 42831 | Y1: 42861 | Z1: 42891 | AA1: 42921 | AB1: 42951 | AC1: 42981 | AD1: 43011 | AE1: 43041 | AF1: 43071 | AG1: 43101 | AH1: 43132 | AI1: 43161 | AJ1: 43191 | AK1: 43221 | AL1: 43281 | AM1: 43311 | AN1: 43341 | AO1: 43371 | AP1: 43401 | AQ1: 43431 | AR1: 43461 | AS1: 43491 | AT1: 43521 | AU1: 43551 | AV1: 43581 | AW1: 43611 | AX1: 43641 | AY1: 43671 | AZ1: 43701 | BA1: 43731 | BB1: 43761 | BC1: 43791 | BD1: 43821 | BE1: 43851 | BF1: 43881 | BG1: 43911 | BH1: 43941 | BI1: 43971 | BJ1: 44001 | BK1: 44031 | BL1: 44061 | BM1: 44091 | BN1: 44121 | BO1: 44151 | BP1: 44181 | BQ1: 44211 | BR1: 44241 | BS1: 44271 | BT1: 44301 | BU1: 44331 | BV1: 44361 | BW1: 44391 | BX1: 44421 | BY1: 44451 | BZ1: 44481 | CA1: 44511 | CB1: 44541 | CC1: 44571 | CD1: 44601 | CE1: 44631 | CF1: 44661 | CG1: 44691 | CH1: 44721 | CI1: 44751 | CJ1: 44781 | CK1: 44811 | CL1: 44841 | CM1: 44871 | CN1: 44901 | CO1: 44931 | CP1: 44961 | CQ1: 44991 | CR1: 45021 | CS1: 45051 | CT1: 45081 | CU1: 45111 | CV1: 45141 | CW1: 45171 | CX1: 45201 | CY1: 45231 | CZ1: 45261 | DA1: 45321 | DB1: 45351 | DC1: 45381 | DD1: 45411 | DE1: 45441 | DF1: 45471 | DG1: 45501 | DH1: 45531 | DI1: 45561 | DJ1: 45591
A2: 1 | B2: 사업1 | C2: 협력1 | D2: 라인2 | E2: 42380 | F2: 43131 | G2: 정규 | H2: 경영악화 | J2: 62.881012 | K2: 48.458754 | L2: 57.913912 | M2: 56.577666 | N2: 55.045919 | O2: 53.996512 | P2: 50.294399 | Q2: 48.913538 | R2: 55.051076 | S2: 56.717147 | T2: 48.196448 | U2: 45.847654 | V2: 46.582881 | W2: 47.58478 | X2: 48.145222 | Y2: 57.526304 | Z2: 57.627893 | AA2: 57.613101 | AB2: 55.298834 | AC2: 56.790841 | AD2: 56.956061 | AE2: 52.279126 | AF2: 54.948202 | AG2: 41.561156 | AH2: 0 | AI2: 0 | AJ2: 0 | AK2: 0 | AL2: 0 | AM2: 0 | AN2: 0 | AO2: 0 | AP2: 0 | AQ2: 0 | AR2: 0 | AS2: 0 | AT2: 0 | AU2: 0 | AV2: 0 | AW2: 0 | AX2: 0 | AY2: 0 | AZ2: 0 | BA2: 0 | BB2: 0 | BC2: 0 | BD2: 0 | BE2: 0 | BF2: 0 | BG2: 0 | BH2: 0 | BI2: 0 | BJ2: 0 | BK2: 0 | BL2: 0 | BM2: 0 | BN2: 0 | BO2: 0 | BP2: 0 | BQ2: 0 | BR2: 0 | BS2: 0 | BT2: 0 | BU2: 0 | BV2: 0 | BW2: 0 | BX2: 0 | BY2: 0 | BZ2: 0 | CA2: 0 | CB2: 0 | CC2: 0 | CD2: 0 | CE2: 0 | CF2: 0 | CG2: 0 | CH2: 0 | CI2: 0 | CJ2: 0 | CK2: 0 | CL2: 0 | CM2: 0 | CN2: 0 | CO2: 0 | CP2: 0 | CQ2: 0 | CR2: 0 | CS2: 0 | CT2: 0 | CU2: 0 | CV2: 0 | CW2: 0 | CX2: 0 | CY2: 0 | CZ2: 0 | DA2: 0 | DB2: 0 | DC2: 0 | DD2: 0 | DE2: 0 | DF2: 0 | DG2: 0 | DH2: 0 | DI2: 0 | DJ2: 0
A3: 2 | B3: 사업1 | C3: 협력1 | D3: 외장1 | E3: 35149 | F3: 43131 | G3: 정규 | H3: 경영악화 | J3: 53.869254 | K3: 52.899405 | L3: 52.333109 | M3: 50.45207 | N3: 54.582994 | O3: 57.206671 | P3: 56.712821 | Q3: 58.956202 | R3: 52.684713 | S3: 52.919909 | T3: 55.560737 | U3: 51.643049 | V3: 39.52862 | W3: 53.182846 | X3: 40.651969 | Y3: 33.307297 | Z3: 40.837689 | AA3: 52.918072 | AB3: 45.742916 | AC3: 49.693293 | AD3: 44.860223 | AE3: 43.942939 | AF3: 57.01908 | AG3: 106.20381 | AH3: 0 | AI3: 0 | AJ3: 0 | AK3: 0 | AL3: 0 | AM3: 0 | AN3: 0 | AO3: 0 | AP3: 0 | AQ3: 0 | AR3: 0 | AS3: 0 | AT3: 0 | AU3: 0 | AV3: 0 | AW3: 0 | AX3: 0 | AY3: 0 | AZ3: 0 | BA3: 0 | BB3: 0 | BC3: 0 | BD3: 0 | BE3: 0 | BF3: 0 | BG3: 0 | BH3: 0 | BI3: 0 | BJ3: 0 | BK3: 0 | BL3: 0 | BM3: 0 | BN3: 0 | BO3: 0 | BP3: 0 | BQ3: 0 | BR3: 0 | BS3: 0 | BT3: 0 | BU3: 0 | BV3: 0 | BW3: 0 | BX3: 0 | BY3: 0 | BZ3: 0 | CA3: 0 | CB3: 0 | CC3: 0 | CD3: 0 | CE3: 0 | CF3: 0 | CG3: 0 | CH3: 0 | CI3: 0 | CJ3: 0 | CK3: 0 | CL3: 0 | CM3: 0 | CN3: 0 | CO3: 0 | CP3: 0 | CQ3: 0 | CR3: 0 | CS3: 0 | CT3: 0 | CU3: 0 | CV3: 0 | CW3: 0 | CX3: 0 | CY3: 0 | CZ3: 0 | DA3: 0 | DB3: 0 | DC3: 0 | DD3: 0 | DE3: 0 | DF3: 0 | DG3: 0 | DH3: 0 | DI3: 0 | DJ3: 0
A4: 3 | B4: 사업1 | C4: 협력1 | D4: 공사 | E4: 38071 | F4: 43159 | G4: 정규 | H4: 경영악화 | J4: 71.349825 | K4: 50.733024 | L4: 48.113309 | M4: 49.318111 | N4: 61.289923 | O4: 60.550594 | P4: 52.588646 | Q4: 54.743425 | R4: 39.950892 | S4: 48.266237 | T4: 50.931214 | U4: 43.09931 | V4: 57.027978 | W4: 70.211739 | X4: 44.105145 | Y4: 65.550335 | Z4: 52.609076 | AA4: 50.307771 | AB4: 57.813808 | AC4: 49.422011 | AD4: 48.375394 | AE4: 57.74885 | AF4: 51.282248 | AG4: 45.108364 | AH4: 52.986268 | AI4: 0 | AJ4: 0 | AK4: 0 | AL4: 0 | AM4: 0 | AN4: 0 | AO4: 0 | AP4: 0 | AQ4: 0 | AR4: 0 | AS4: 0 | AT4: 0 | AU4: 0 | AV4: 0 | AW4: 0 | AX4: 0 | AY4: 0 | AZ4: 0 | BA4: 0 | BB4: 0 | BC4: 0 | BD4: 0 | BE4: 0 | BF4: 0 | BG4: 0 | BH4: 0 | BI4: 0 | BJ4: 0 | BK4: 0 | BL4: 0 | BM4: 0 | BN4: 0 | BO4: 0 | BP4: 0 | BQ4: 0 | BR4: 0 | BS4: 0 | BT4: 0 | BU4: 0 | BV4: 0 | BW4: 0 | BX4: 0 | BY4: 0 | BZ4: 0 | CA4: 0 | CB4: 0 | CC4: 0 | CD4: 0 | CE4: 0 | CF4: 0 | CG4: 0 | CH4: 0 | CI4: 0 | CJ4: 0 | CK4: 0 | CL4: 0 | CM4: 0 | CN4: 0 | CO4: 0 | CP4: 0 | CQ4: 0 | CR4: 0 | CS4: 0 | CT4: 0 | CU4: 0 | CV4: 0 | CW4: 0 | CX4: 0 | CY4: 0 | CZ4: 0 | DA4: 0 | DB4: 0 | DC4: 0 | DD4: 0 | DE4: 0 | DF4: 0 | DG4: 0 | DH4: 0 | DI4: 0 | DJ4: 0
A5: 4 | B5: 사업2 | C5: 협력1 | D5: 라인2 | E5: 42292 | F5: 43190 | G5: 정규 | H5: 경영악화 | J5: 58.203513 | K5: 34.551018 | L5: 58.690465 | M5: 47.098736 | N5: 43.756137 | O5: 82.084823 | P5: 62.970935 | Q5: 34.572997 | R5: 38.355815 | S5: 33.866046 | T5: 42.406341 | U5: 61.845778 | V5: 56.746962 | W5: 48.034117 | X5: 55.459403 | Y5: 47.36441 | Z5: 50.2474 | AA5: 51.233057 | AB5: 56.710774 | AC5: 53.248743 | AD5: 65.891519 | AE5: 59.935313 | AF5: 52.455107 | AG5: 53.911559 | AH5: 30.810093 | AI5: 73.927959 | AJ5: 0 | AK5: 0 | AL5: 0 | AM5: 0 | AN5: 0 | AO5: 0 | AP5: 0 | AQ5: 0 | AR5: 0 | AS5: 0 | AT5: 0 | AU5: 0 | AV5: 0 | AW5: 0 | AX5: 0 | AY5: 0 | AZ5: 0 | BA5: 0 | BB5: 0 | BC5: 0 | BD5: 0 | BE5: 0 | BF5: 0 | BG5: 0 | BH5: 0 | BI5: 0 | BJ5: 0 | BK5: 0 | BL5: 0 | BM5: 0 | BN5: 0 | BO5: 0 | BP5: 0 | BQ5: 0 | BR5: 0 | BS5: 0 | BT5: 0 | BU5: 0 | BV5: 0 | BW5: 0 | BX5: 0 | BY5: 0 | BZ5: 0 | CA5: 0 | CB5: 0 | CC5: 0 | CD5: 0 | CE5: 0 | CF5: 0 | CG5: 0 | CH5: 0 | CI5: 0 | CJ5: 0 | CK5: 0 | CL5: 0 | CM5: 0 | CN5: 0 | CO5: 0 | CP5: 0 | CQ5: 0 | CR5: 0 | CS5: 0 | CT5: 0 | CU5: 0 | CV5: 0 | CW5: 0 | CX5: 0 | CY5: 0 | CZ5: 0 | DA5: 0 | DB5: 0 | DC5: 0 | DD5: 0 | DE5: 0 | DF5: 0 | DG5: 0 | DH5: 0 | DI5: 0 | DJ5: 0
A6: 5 | B6: 사업1 | C6: 협력1 | D6: 공사 | E6: 43161 | F6: 43312 | G6: 정규 | H6: 경영악화 | J6: 0 | K6: 0 | L6: 0 | M6: 0 | N6: 0 | O6: 0 | P6: 0 | Q6: 0 | R6: 0 | S6: 0 | T6: 0 | U6: 0 | V6: 0 | W6: 0 | X6: 0 | Y6: 0 | Z6: 0 | AA6: 0 | AB6: 0 | AC6: 0 | AD6: 0 | AE6: 0 | AF6: 0 | AG6: 0 | AH6: 0 | AI6: 55.172302 | AJ6: 53.229609 | AK6: 56.34348 | AL6: 52.372224 | AM6: 49.6307 | AN6: 0 | AO6: 0 | AP6: 0 | AQ6: 0 | AR6: 0 | AS6: 0 | AT6: 0 | AU6: 0 | AV6: 0 | AW6: 0 | AX6: 0 | AY6: 0 | AZ6: 0 | BA6: 0 | BB6: 0 | BC6: 0 | BD6: 0 | BE6: 0 | BF6: 0 | BG6: 0 | BH6: 0 | BI6: 0 | BJ6: 0 | BK6: 0 | BL6: 0 | BM6: 0 | BN6: 0 | BO6: 0 | BP6: 0 | BQ6: 0 | BR6: 0 | BS6: 0 | BT6: 0 | BU6: 0 | BV6: 0 | BW6: 0 | BX6: 0 | BY6: 0 | BZ6: 0 | CA6: 0 | CB6: 0 | CC6: 0 | CD6: 0 | CE6: 0 | CF6: 0 | CG6: 0 | CH6: 0 | CI6: 0 | CJ6: 0 | CK6: 0 | CL6: 0 | CM6: 0 | CN6: 0 | CO6: 0 | CP6: 0 | CQ6: 0 | CR6: 0 | CS6: 0 | CT6: 0 | CU6: 0 | CV6: 0 | CW6: 0 | CX6: 0 | CY6: 0 | CZ6: 0 | DA6: 0 | DB6: 0 | DC6: 0 | DD6: 0 | DE6: 0 | DF6: 0 | DG6: 0 | DH6: 0 | DI6: 0 | DJ6: 0
A7: 6 | B7: 사업2 | C7: 협력1 | D7: 라인2 | E7: 37956 | F7: 43312 | G7: 정규 | H7: 경영악화 | J7: 59.528322 | K7: 52.700183 | L7: 60.441993 | M7: 62.915698 | N7: 61.13757 | O7: 62.125183 | P7: 38.174076 | Q7: 25.972861 | R7: 31.149987 | S7: 33.344155 | T7: 33.565546 | U7: 35.186243 | V7: 24.66656 | W7: 26.474242 | X7: 24.201071 | Y7: 31.145468 | Z7: 28.047137 | AA7: 38.344141 | AB7: 58.460836 | AC7: 64.233472 | AD7: 59.521314 | AE7: 46.094518 | AF7: 55.565724 | AG7: 60.978031 | AH7: 60.853175 | AI7: 58.032643 | AJ7: 54.656778 | AK7: 63.821903 | AL7: 60.4 | AM7: 62.170232 | AN7: 0 | AO7: 0 | AP7: 0 | AQ7: 0 | AR7: 0 | AS7: 0 | AT7: 0 | AU7: 0 | AV7: 0 | AW7: 0 | AX7: 0 | AY7: 0 | AZ7: 0 | BA7: 0 | BB7: 0 | BC7: 0 | BD7: 0 | BE7: 0 | BF7: 0 | BG7: 0 | BH7: 0 | BI7: 0 | BJ7: 0 | BK7: 0 | BL7: 0 | BM7: 0 | BN7: 0 | BO7: 0 | BP7: 0 | BQ7: 0 | BR7: 0 | BS7: 0 | BT7: 0 | BU7: 0 | BV7: 0 | BW7: 0 | BX7: 0 | BY7: 0 | BZ7: 0 | CA7: 0 | CB7: 0 | CC7: 0 | CD7: 0 | CE7: 0 | CF7: 0 | CG7: 0 | CH7: 0 | CI7: 0 | CJ7: 0 | CK7: 0 | CL7: 0 | CM7: 0 | CN7: 0 | CO7: 0 | CP7: 0 | CQ7: 0 | CR7: 0 | CS7: 0 | CT7: 0 | CU7: 0 | CV7: 0 | CW7: 0 | CX7: 0 | CY7: 0 | CZ7: 0 | DA7: 0 | DB7: 0 | DC7: 0 | DD7: 0 | DE7: 0 | DF7: 0 | DG7: 0 | DH7: 0 | DI7: 0 | DJ7: 0
A8: 7 | B8: 사업1 | C8: 협력1 | D8: 외장1 | E8: 39783 | F8: 43570 | G8: 정규 | H8: 경영악화 | J8: 59.191855 | K8: 54.099909 | L8: 55.947347 | M8: 56.001415 | N8: 54.368521 | O8: 63.104486 | P8: 61.012801 | Q8: 59.473959 | R8: 62.552824 | S8: 58.764217 | T8: 60.648161 | U8: 52.405172 | V8: 45.583254 | W8: 53.662002 | X8: 51.643636 | Y8: 51.586768 | Z8: 51.767593 | AA8: 54.221864 | AB8: 51.255747 | AC8: 54.272683 | AD8: 57.302467 | AE8: 56.45738 | AF8: 57.232378 | AG8: 54.472337 | AH8: 57.225383 | AI8: 51.719289 | AJ8: 53.366133 | AK8: 68.763735 | AL8: 57.62079 | AM8: 61.339059 | AN8: 60.202647 | AO8: 57.696659 | AP8: 0 | AQ8: 0 | AR8: 0 | AS8: 0 | AT8: 0 | AU8: 0 | AV8: 0 | AW8: 0 | AX8: 0 | AY8: 0 | AZ8: 0 | BA8: 0 | BB8: 0 | BC8: 0 | BD8: 0 | BE8: 0 | BF8: 0 | BG8: 0 | BH8: 0 | BI8: 0 | BJ8: 0 | BK8: 0 | BL8: 0 | BM8: 0 | BN8: 0 | BO8: 0 | BP8: 0 | BQ8: 0 | BR8: 0 | BS8: 0 | BT8: 0 | BU8: 0 | BV8: 0 | BW8: 0 | BX8: 0 | BY8: 0 | BZ8: 0 | CA8: 0 | CB8: 0 | CC8: 0 | CD8: 0 | CE8: 0 | CF8: 0 | CG8: 0 | CH8: 0 | CI8: 0 | CJ8: 0 | CK8: 0 | CL8: 0 | CM8: 0 | CN8: 0 | CO8: 0 | CP8: 0 | CQ8: 0 | CR8: 0 | CS8: 0 | CT8: 0 | CU8: 0 | CV8: 0 | CW8: 0 | CX8: 0 | CY8: 0 | CZ8: 0 | DA8: 0 | DB8: 0 | DC8: 0 | DD8: 0 | DE8: 0 | DF8: 0 | DG8: 0 | DH8: 0 | DI8: 0 | DJ8: 0
A9: 8 | B9: 사업1 | C9: 협력1 | D9: 공사 | E9: 43161 | F9: 43793 | G9: 정규 | H9: 경영악화 | J9: 0 | K9: 0 | L9: 0 | M9: 0 | N9: 0 | O9: 0 | P9: 0 | Q9: 0 | R9: 0 | S9: 0 | T9: 0 | U9: 0 | V9: 0 | W9: 0 | X9: 0 | Y9: 0 | Z9: 0 | AA9: 0 | AB9: 0 | AC9: 0 | AD9: 0 | AE9: 0 | AF9: 0 | AG9: 0 | AH9: 0 | AI9: 56.207704 | AJ9: 58.540876 | AK9: 58.077774 | AL9: 48.579468 | AM9: 58.383283 | AN9: 55.767894 | AO9: 52.482702 | AP9: 44.099721 | AQ9: 59.567629 | AR9: 47.558245 | AS9: 44.208163 | AT9: 79.065343 | AU9: 0 | AV9: 0 | AW9: 0 | AX9: 32.30814 | AY9: 46.497874 | AZ9: 55.398211 | BA9: 45.714258 | BB9: 51.878196 | BC9: 40.985864 | BD9: 0 | BE9: 0 | BF9: 0 | BG9: 0 | BH9: 0 | BI9: 0 | BJ9: 0 | BK9: 0 | BL9: 0 | BM9: 0 | BN9: 0 | BO9: 0 | BP9: 0 | BQ9: 0 | BR9: 0 | BS9: 0 | BT9: 0 | BU9: 0 | BV9: 0 | BW9: 0 | BX9: 0 | BY9: 0 | BZ9: 0 | CA9: 0 | CB9: 0 | CC9: 0 | CD9: 0 | CE9: 0 | CF9: 0 | CG9: 0 | CH9: 0 | CI9: 0 | CJ9: 0 | CK9: 0 | CL9: 0 | CM9: 0 | CN9: 0 | CO9: 0 | CP9: 0 | CQ9: 0 | CR9: 0 | CS9: 0 | CT9: 0 | CU9: 0 | CV9: 0 | CW9: 0 | CX9: 0 | CY9: 0 | CZ9: 0 | DA9: 0 | DB9: 0 | DC9: 0 | DD9: 0 | DE9: 0 | DF9: 0 | DG9: 0 | DH9: 0 | DI9: 0 | DJ9: 0
A10: 9 | B10: 사업1 | C10: 협력2 | D10: 지원 | E10: 39203 | F10: 43799 | G10: 정규 | H10: 경영악화 | J10: 56.463659 | K10: 50.893442 | L10: 50.287961 | M10: 48.536611 | N10: 54.757331 | O10: 53.954747 | P10: 42.224705 | Q10: 56.638481 | R10: 47.599911 | S10: 45.349513 | T10: 42.120175 | U10: 52.728591 | V10: 59.096333 | W10: 61.030133 | X10: 62.067479 | Y10: 72.983486 | Z10: 95.533906 | AA10: 66.727633 | AB10: 64.005207 | AC10: 61.520211 | AD10: 66.087618 | AE10: 60.746797 | AF10: 64.999524 | AG10: 34.515181 | AH10: 72.528555 | AI10: 50.076388 | AJ10: 47.759265 | AK10: 61.717755 | AL10: 66.343188 | AM10: 62.502249 | AN10: 63.874799 | AO10: 52.854697 | AP10: 49.42446 | AQ10: 62.27136 | AR10: 52.365993 | AS10: 44.244759 | AT10: 51.598887 | AU10: 40.262326 | AV10: 68.208084 | AW10: 51.088781 | AX10: 47.967859 | AY10: 49.451296 | AZ10: 55.561875 | BA10: 56.650236 | BB10: 54.245693 | BC10: 44.863015 | BD10: 0 | BE10: 0 | BF10: 0 | BG10: 0 | BH10: 0 | BI10: 0 | BJ10: 0 | BK10: 0 | BL10: 0 | BM10: 0 | BN10: 0 | BO10: 0 | BP10: 0 | BQ10: 0 | BR10: 0 | BS10: 0 | BT10: 0 | BU10: 0 | BV10: 0 | BW10: 0 | BX10: 0 | BY10: 0 | BZ10: 0 | CA10: 0 | CB10: 0 | CC10: 0 | CD10: 0 | CE10: 0 | CF10: 0 | CG10: 0 | CH10: 0 | CI10: 0 | CJ10: 0 | CK10: 0 | CL10: 0 | CM10: 0 | CN10: 0 | CO10: 0 | CP10: 0 | CQ10: 0 | CR10: 0 | CS10: 0 | CT10: 0 | CU10: 0 | CV10: 0 | CW10: 0 | CX10: 0 | CY10: 0 | CZ10: 0 | DA10: 0 | DB10: 0 | DC10: 0 | DD10: 0 | DE10: 0 | DF10: 0 | DG10: 0 | DH10: 0 | DI10: 0 | DJ10: 0
A11: 10 | B11: 사업2 | C11: 협력1 | D11: 외장1 | E11: 41836 | F11: 43814 | G11: 정규 | H11: 경영악화 | J11: 58.091823 | K11: 54.132238 | L11: 57.696201 | M11: 56.909846 | N11: 62.355347 | O11: 64.911861 | P11: 50.319414 | Q11: 41.289318 | R11: 36.114069 | S11: 29.113024 | T11: 67.16616 | U11: 41.731415 | V11: 39.6791 | W11: 26.817186 | X11: 34.647772 | Y11: 53.925253 | Z11: 51.762921 | AA11: 52.891085 | AB11: 50.328158 | AC11: 54.509884 | AD11: 52.355841 | AE11: 55.12732 | AF11: 56.089638 | AG11: 50.317183 | AH11: 52.194868 | AI11: 47.947023 | AJ11: 57.447512 | AK11: 55.004136 | AL11: 65.045563 | AM11: 68.813746 | AN11: 79.974943 | AO11: 78.001898 | AP11: 79.881657 | AQ11: 72.106185 | AR11: 100 | AS11: 52.732884 | AT11: 71.25448 | AU11: 61.03504 | AV11: 51.968085 | AW11: 57.528307 | AX11: 36.441356 | AY11: 43.435291 | AZ11: 48.1874 | BA11: 49.623877 | BB11: 41.892716 | BC11: 28.819587 | BD11: 31.913919 | BE11: 0 | BF11: 0 | BG11: 0 | BH11: 0 | BI11: 0 | BJ11: 0 | BK11: 0 | BL11: 0 | BM11: 0 | BN11: 0 | BO11: 0 | BP11: 0 | BQ11: 0 | BR11: 0 | BS11: 0 | BT11: 0 | BU11: 0 | BV11: 0 | BW11: 0 | BX11: 0 | BY11: 0 | BZ11: 0 | CA11: 0 | CB11: 0 | CC11: 0 | CD11: 0 | CE11: 0 | CF11: 0 | CG11: 0 | CH11: 0 | CI11: 0 | CJ11: 0 | CK11: 0 | CL11: 0 | CM11: 0 | CN11: 0 | CO11: 0 | CP11: 0 | CQ11: 0 | CR11: 0 | CS11: 0 | CT11: 0 | CU11: 0 | CV11: 0 | CW11: 0 | CX11: 0 | CY11: 0 | CZ11: 0 | DA11: 0 | DB11: 0 | DC11: 0 | DD11: 0 | DE11: 0 | DF11: 0 | DG11: 0 | DH11: 0 | DI11: 0 | DJ11: 0
A12: 11 | B12: 사업1 | C12: 협력2 | D12: 공사 | E12: 40238 | F12: 44165 | G12: 정규 | H12: 경영악화 | J12: 54.470073 | K12: 42.851562 | L12: 45.53273 | M12: 42.525321 | N12: 36.308238 | O12: 40.020519 | P12: 40.796544 | Q12: 43.759217 | R12: 43.546484 | S12: 54.490036 | T12: 52.106029 | U12: 67.428049 | V12: 68.810157 | W12: 59.283589 | X12: 65.937256 | Y12: 71.017589 | Z12: 62.553104 | AA12: 58.444279 | AB12: 39.874543 | AC12: 50.582447 | AD12: 42.480837 | AE12: 50.175765 | AF12: 48.835589 | AG12: 69.191494 | AH12: 64.876136 | AI12: 70.475388 | AJ12: 61.026404 | AK12: 74.083344 | AL12: 77.978754 | AM12: 56.251538 | AN12: 52.677029 | AO12: 49.315827 | AP12: 42.870813 | AQ12: 57.232065 | AR12: 58.158476 | AS12: 52.447625 | AT12: 58.612109 | AU12: 51.247673 | AV12: 55.60509 | AW12: 56.422614 | AX12: 63.911757 | AY12: 54.555846 | AZ12: 64.27323 | BA12: 58.862526 | BB12: 55.598285 | BC12: 60.857051 | BD12: 45.787183 | BE12: 46.440865 | BF12: 0 | BG12: 7.0744195 | BH12: 26.693973 | BI12: 78.603306 | BJ12: 59.141207 | BK12: 31.825135 | BL12: 29.307379 | BM12: 51.268234 | BN12: 44.380881 | BO12: 137.0297 | BP12: 0 | BQ12: 0 | BR12: 0 | BS12: 0 | BT12: 0 | BU12: 0 | BV12: 0 | BW12: 0 | BX12: 0 | BY12: 0 | BZ12: 0 | CA12: 0 | CB12: 0 | CC12: 0 | CD12: 0 | CE12: 0 | CF12: 0 | CG12: 0 | CH12: 0 | CI12: 0 | CJ12: 0 | CK12: 0 | CL12: 0 | CM12: 0 | CN12: 0 | CO12: 0 | CP12: 0 | CQ12: 0 | CR12: 0 | CS12: 0 | CT12: 0 | CU12: 0 | CV12: 0 | CW12: 0 | CX12: 0 | CY12: 0 | CZ12: 0 | DA12: 0 | DB12: 0 | DC12: 0 | DD12: 0 | DE12: 0 | DF12: 0 | DG12: 0 | DH12: 0 | DI12: 0 | DJ12: 0
A13: 12 | B13: 사업1 | C13: 협력2 | D13: 공사 | E13: 42339 | F13: 44196 | G13: 정규 | H13: 경영악화 | J13: 57.365143 | K13: 49.830037 | L13: 52.776594 | M13: 48.020581 | N13: 50.279232 | O13: 50.985628 | P13: 70.504354 | Q13: 57.4331 | R13: 63.633285 | S13: 59.468794 | T13: 54.217558 | U13: 63.229204 | V13: 58.163139 | W13: 55.743009 | X13: 63.369305 | Y13: 64.724115 | Z13: 57.933872 | AA13: 61.077963 | AB13: 50.238734 | AC13: 70.395312 | AD13: 55.31036 | AE13: 61.642159 | AF13: 55.072816 | AG13: 60.357773 | AH13: 83.822076 | AI13: 74.853114 | AJ13: 64.450806 | AK13: 56.18431 | AL13: 70.251152 | AM13: 71.830818 | AN13: 67.569214 | AO13: 47.974217 | AP13: 54.734572 | AQ13: 70.557408 | AR13: 71.775062 | AS13: 67.871798 | AT13: 66.661426 | AU13: 53.196299 | AV13: 49.81349 | AW13: 73.733711 | AX13: 66.189112 | AY13: 59.612071 | AZ13: 69.530677 | BA13: 66.443967 | BB13: 55.169626 | BC13: 56.921905 | BD13: 41.29495 | BE13: 0 | BF13: 27.887048 | BG13: 40.580561 | BH13: 28.772868 | BI13: 32.847751 | BJ13: 44.447816 | BK13: 37.868203 | BL13: 43.947255 | BM13: 54.717227 | BN13: 52.835255 | BO13: 33.552511 | BP13: 30.644969 | BQ13: 0 | BR13: 0 | BS13: 0 | BT13: 0 | BU13: 0 | BV13: 0 | BW13: 0 | BX13: 0 | BY13: 0 | BZ13: 0 | CA13: 0 | CB13: 0 | CC13: 0 | CD13: 0 | CE13: 0 | CF13: 0 | CG13: 0 | CH13: 0 | CI13: 0 | CJ13: 0 | CK13: 0 | CL13: 0 | CM13: 0 | CN13: 0 | CO13: 0 | CP13: 0 | CQ13: 0 | CR13: 0 | CS13: 0 | CT13: 0 | CU13: 0 | CV13: 0 | CW13: 0 | CX13: 0 | CY13: 0 | CZ13: 0 | DA13: 0 | DB13: 0 | DC13: 0 | DD13: 0 | DE13: 0 | DF13: 0 | DG13: 0 | DH13: 0 | DI13: 0 | DJ13: 0
